2021-01-26 02:58:14,811 WARNING libqtile manager.py:maybe_restart():L269 Restarting Qtile with os.execv(...)
2021-01-26 03:00:23,150 WARNING libqtile manager.py:maybe_restart():L269 Restarting Qtile with os.execv(...)
2021-01-26 03:00:35,184 WARNING libqtile manager.py:maybe_restart():L269 Restarting Qtile with os.execv(...)
2021-01-26 03:16:01,729 WARNING libqtile manager.py:maybe_restart():L269 Restarting Qtile with os.execv(...)
2021-01-26 03:29:18,023 WARNING libqtile manager.py:maybe_restart():L269 Restarting Qtile with os.execv(...)
2021-01-26 03:29:25,630 WARNING libqtile manager.py:maybe_restart():L269 Restarting Qtile with os.execv(...)
2021-01-26 03:30:32,663 ERROR libqtile xcore.py:_xpoll():L269 Shutting down due to X connection error XCB_CONN_ERROR (1)
Traceback (most recent call last):
  File "/usr/lib/python3.9/site-packages/xcffib/__init__.py", line 571, in wrapper
    return f(*args)
  File "/usr/lib/python3.9/site-packages/xcffib/__init__.py", line 610, in poll_for_event
    self.invalid()
  File "/usr/lib/python3.9/site-packages/xcffib/__init__.py", line 559, in invalid
    raise ConnectionException(err)
xcffib.ConnectionException: xcb connection errors because of socket, pipe and other stream errors.

During handling of the above exception, another exception occurred:

Traceback (most recent call last):
  File "/usr/lib/python3.9/site-packages/libqtile/backend/x11/xcore.py", line 230, in _xpoll
    event = self.conn.conn.poll_for_event()
  File "/usr/lib/python3.9/site-packages/xcffib/__init__.py", line 573, in wrapper
    self.invalid()
  File "/usr/lib/python3.9/site-packages/xcffib/__init__.py", line 559, in invalid
    raise ConnectionException(err)
xcffib.ConnectionException: xcb connection errors because of socket, pipe and other stream errors.
2021-01-26 03:30:32,665 ERROR libqtile manager.py:get_interesting_pid():L631 Got an exception in getting the window pid
Traceback (most recent call last):
  File "/usr/lib/python3.9/site-packages/xcffib/__init__.py", line 571, in wrapper
    return f(*args)
  File "/usr/lib/python3.9/site-packages/xcffib/__init__.py", line 610, in poll_for_event
    self.invalid()
  File "/usr/lib/python3.9/site-packages/xcffib/__init__.py", line 559, in invalid
    raise ConnectionException(err)
xcffib.ConnectionException: xcb connection errors because of socket, pipe and other stream errors.

During handling of the above exception, another exception occurred:

Traceback (most recent call last):
  File "/usr/lib/python3.9/site-packages/libqtile/backend/x11/xcore.py", line 230, in _xpoll
    event = self.conn.conn.poll_for_event()
  File "/usr/lib/python3.9/site-packages/xcffib/__init__.py", line 573, in wrapper
    self.invalid()
  File "/usr/lib/python3.9/site-packages/xcffib/__init__.py", line 559, in invalid
    raise ConnectionException(err)
xcffib.ConnectionException: xcb connection errors because of socket, pipe and other stream errors.

During handling of the above exception, another exception occurred:

Traceback (most recent call last):
  File "/usr/lib/python3.9/site-packages/libqtile/core/manager.py", line 629, in get_interesting_pid
    return win.window.get_net_wm_pid()
  File "/usr/lib/python3.9/site-packages/libqtile/backend/x11/xcbq.py", line 612, in get_net_wm_pid
    r = self.get_property("_NET_WM_PID", unpack=int)
  File "/usr/lib/python3.9/site-packages/libqtile/backend/x11/xcbq.py", line 705, in get_property
    r = self.conn.conn.core.GetProperty(
  File "/usr/lib/python3.9/site-packages/xcffib/xproto.py", line 2720, in GetProperty
    return self.send_request(20, buf, GetPropertyCookie, is_checked=is_checked)
  File "/usr/lib/python3.9/site-packages/xcffib/__init__.py", line 391, in send_request
    seq = self.conn.send_request(flags, xcb_parts + 2, xcb_req)
  File "/usr/lib/python3.9/site-packages/xcffib/__init__.py", line 569, in wrapper
    self.invalid()
  File "/usr/lib/python3.9/site-packages/xcffib/__init__.py", line 559, in invalid
    raise ConnectionException(err)
xcffib.ConnectionException: xcb connection errors because of socket, pipe and other stream errors.
2021-01-26 03:30:32,675 ERROR libqtile manager.py:finalize():L320 exception during finalize
Traceback (most recent call last):
  File "/usr/lib/python3.9/site-packages/libqtile/core/manager.py", line 310, in finalize
    widget.finalize()
  File "/usr/lib/python3.9/site-packages/libqtile/widget/base.py", line 208, in finalize
    self.drawer.finalize()
  File "/usr/lib/python3.9/site-packages/libqtile/drawer.py", line 247, in finalize
    self.qtile.conn.conn.core.FreeGC(self.gc)
  File "/usr/lib/python3.9/site-packages/xcffib/xproto.py", line 3027, in FreeGC
    return self.send_request(60, buf, is_checked=is_checked)
  File "/usr/lib/python3.9/site-packages/xcffib/__init__.py", line 391, in send_request
    seq = self.conn.send_request(flags, xcb_parts + 2, xcb_req)
  File "/usr/lib/python3.9/site-packages/xcffib/__init__.py", line 569, in wrapper
    self.invalid()
  File "/usr/lib/python3.9/site-packages/xcffib/__init__.py", line 559, in invalid
    raise ConnectionException(err)
xcffib.ConnectionException: xcb connection errors because of socket, pipe and other stream errors.
2021-01-26 03:38:17,586 WARNING libqtile manager.py:maybe_restart():L269 Restarting Qtile with os.execv(...)
2021-01-26 03:39:07,491 ERROR libqtile manager.py:handle_exception():L77 xcb connection errors because of socket, pipe and other stream errors.
Traceback (most recent call last):
  File "/usr/lib/python3.9/asyncio/events.py", line 80, in _run
    self._context.run(self._callback, *self._args)
  File "/usr/lib/python3.9/site-packages/libqtile/core/manager.py", line 914, in f
    self.conn.flush()
  File "/usr/lib/python3.9/site-packages/libqtile/backend/x11/xcbq.py", line 899, in flush
    return self.conn.flush()
  File "/usr/lib/python3.9/site-packages/xcffib/__init__.py", line 573, in wrapper
    self.invalid()
  File "/usr/lib/python3.9/site-packages/xcffib/__init__.py", line 559, in invalid
    raise ConnectionException(err)
xcffib.ConnectionException: xcb connection errors because of socket, pipe and other stream errors.
2021-01-26 03:39:07,493 ERROR libqtile manager.py:get_interesting_pid():L631 Got an exception in getting the window pid
Traceback (most recent call last):
  File "/usr/lib/python3.9/site-packages/libqtile/core/manager.py", line 629, in get_interesting_pid
    return win.window.get_net_wm_pid()
  File "/usr/lib/python3.9/site-packages/libqtile/backend/x11/xcbq.py", line 612, in get_net_wm_pid
    r = self.get_property("_NET_WM_PID", unpack=int)
  File "/usr/lib/python3.9/site-packages/libqtile/backend/x11/xcbq.py", line 705, in get_property
    r = self.conn.conn.core.GetProperty(
  File "/usr/lib/python3.9/site-packages/xcffib/xproto.py", line 2720, in GetProperty
    return self.send_request(20, buf, GetPropertyCookie, is_checked=is_checked)
  File "/usr/lib/python3.9/site-packages/xcffib/__init__.py", line 391, in send_request
    seq = self.conn.send_request(flags, xcb_parts + 2, xcb_req)
  File "/usr/lib/python3.9/site-packages/xcffib/__init__.py", line 569, in wrapper
    self.invalid()
  File "/usr/lib/python3.9/site-packages/xcffib/__init__.py", line 559, in invalid
    raise ConnectionException(err)
xcffib.ConnectionException: xcb connection errors because of socket, pipe and other stream errors.
2021-01-26 03:39:07,494 ERROR libqtile manager.py:get_interesting_pid():L631 Got an exception in getting the window pid
Traceback (most recent call last):
  File "/usr/lib/python3.9/site-packages/libqtile/core/manager.py", line 629, in get_interesting_pid
    return win.window.get_net_wm_pid()
  File "/usr/lib/python3.9/site-packages/libqtile/backend/x11/xcbq.py", line 612, in get_net_wm_pid
    r = self.get_property("_NET_WM_PID", unpack=int)
  File "/usr/lib/python3.9/site-packages/libqtile/backend/x11/xcbq.py", line 705, in get_property
    r = self.conn.conn.core.GetProperty(
  File "/usr/lib/python3.9/site-packages/xcffib/xproto.py", line 2720, in GetProperty
    return self.send_request(20, buf, GetPropertyCookie, is_checked=is_checked)
  File "/usr/lib/python3.9/site-packages/xcffib/__init__.py", line 391, in send_request
    seq = self.conn.send_request(flags, xcb_parts + 2, xcb_req)
  File "/usr/lib/python3.9/site-packages/xcffib/__init__.py", line 569, in wrapper
    self.invalid()
  File "/usr/lib/python3.9/site-packages/xcffib/__init__.py", line 559, in invalid
    raise ConnectionException(err)
xcffib.ConnectionException: xcb connection errors because of socket, pipe and other stream errors.
2021-01-26 03:39:07,494 ERROR libqtile xcore.py:_xpoll():L269 Shutting down due to X connection error XCB_CONN_ERROR (1)
Traceback (most recent call last):
  File "/usr/lib/python3.9/site-packages/libqtile/backend/x11/xcore.py", line 230, in _xpoll
    event = self.conn.conn.poll_for_event()
  File "/usr/lib/python3.9/site-packages/xcffib/__init__.py", line 569, in wrapper
    self.invalid()
  File "/usr/lib/python3.9/site-packages/xcffib/__init__.py", line 559, in invalid
    raise ConnectionException(err)
xcffib.ConnectionException: xcb connection errors because of socket, pipe and other stream errors.
2021-01-26 03:39:07,495 ERROR libqtile manager.py:get_interesting_pid():L631 Got an exception in getting the window pid
Traceback (most recent call last):
  File "/usr/lib/python3.9/site-packages/libqtile/backend/x11/xcore.py", line 230, in _xpoll
    event = self.conn.conn.poll_for_event()
  File "/usr/lib/python3.9/site-packages/xcffib/__init__.py", line 569, in wrapper
    self.invalid()
  File "/usr/lib/python3.9/site-packages/xcffib/__init__.py", line 559, in invalid
    raise ConnectionException(err)
xcffib.ConnectionException: xcb connection errors because of socket, pipe and other stream errors.

During handling of the above exception, another exception occurred:

Traceback (most recent call last):
  File "/usr/lib/python3.9/site-packages/libqtile/core/manager.py", line 629, in get_interesting_pid
    return win.window.get_net_wm_pid()
  File "/usr/lib/python3.9/site-packages/libqtile/backend/x11/xcbq.py", line 612, in get_net_wm_pid
    r = self.get_property("_NET_WM_PID", unpack=int)
  File "/usr/lib/python3.9/site-packages/libqtile/backend/x11/xcbq.py", line 705, in get_property
    r = self.conn.conn.core.GetProperty(
  File "/usr/lib/python3.9/site-packages/xcffib/xproto.py", line 2720, in GetProperty
    return self.send_request(20, buf, GetPropertyCookie, is_checked=is_checked)
  File "/usr/lib/python3.9/site-packages/xcffib/__init__.py", line 391, in send_request
    seq = self.conn.send_request(flags, xcb_parts + 2, xcb_req)
  File "/usr/lib/python3.9/site-packages/xcffib/__init__.py", line 569, in wrapper
    self.invalid()
  File "/usr/lib/python3.9/site-packages/xcffib/__init__.py", line 559, in invalid
    raise ConnectionException(err)
xcffib.ConnectionException: xcb connection errors because of socket, pipe and other stream errors.
2021-01-26 03:39:07,495 ERROR libqtile manager.py:get_interesting_pid():L631 Got an exception in getting the window pid
Traceback (most recent call last):
  File "/usr/lib/python3.9/site-packages/libqtile/backend/x11/xcore.py", line 230, in _xpoll
    event = self.conn.conn.poll_for_event()
  File "/usr/lib/python3.9/site-packages/xcffib/__init__.py", line 569, in wrapper
    self.invalid()
  File "/usr/lib/python3.9/site-packages/xcffib/__init__.py", line 559, in invalid
    raise ConnectionException(err)
xcffib.ConnectionException: xcb connection errors because of socket, pipe and other stream errors.

During handling of the above exception, another exception occurred:

Traceback (most recent call last):
  File "/usr/lib/python3.9/site-packages/libqtile/core/manager.py", line 629, in get_interesting_pid
    return win.window.get_net_wm_pid()
  File "/usr/lib/python3.9/site-packages/libqtile/backend/x11/xcbq.py", line 612, in get_net_wm_pid
    r = self.get_property("_NET_WM_PID", unpack=int)
  File "/usr/lib/python3.9/site-packages/libqtile/backend/x11/xcbq.py", line 705, in get_property
    r = self.conn.conn.core.GetProperty(
  File "/usr/lib/python3.9/site-packages/xcffib/xproto.py", line 2720, in GetProperty
    return self.send_request(20, buf, GetPropertyCookie, is_checked=is_checked)
  File "/usr/lib/python3.9/site-packages/xcffib/__init__.py", line 391, in send_request
    seq = self.conn.send_request(flags, xcb_parts + 2, xcb_req)
  File "/usr/lib/python3.9/site-packages/xcffib/__init__.py", line 569, in wrapper
    self.invalid()
  File "/usr/lib/python3.9/site-packages/xcffib/__init__.py", line 559, in invalid
    raise ConnectionException(err)
xcffib.ConnectionException: xcb connection errors because of socket, pipe and other stream errors.
2021-01-26 03:39:07,503 ERROR libqtile manager.py:finalize():L320 exception during finalize
Traceback (most recent call last):
  File "/usr/lib/python3.9/site-packages/libqtile/core/manager.py", line 310, in finalize
    widget.finalize()
  File "/usr/lib/python3.9/site-packages/libqtile/widget/base.py", line 208, in finalize
    self.drawer.finalize()
  File "/usr/lib/python3.9/site-packages/libqtile/drawer.py", line 247, in finalize
    self.qtile.conn.conn.core.FreeGC(self.gc)
  File "/usr/lib/python3.9/site-packages/xcffib/xproto.py", line 3027, in FreeGC
    return self.send_request(60, buf, is_checked=is_checked)
  File "/usr/lib/python3.9/site-packages/xcffib/__init__.py", line 391, in send_request
    seq = self.conn.send_request(flags, xcb_parts + 2, xcb_req)
  File "/usr/lib/python3.9/site-packages/xcffib/__init__.py", line 569, in wrapper
    self.invalid()
  File "/usr/lib/python3.9/site-packages/xcffib/__init__.py", line 559, in invalid
    raise ConnectionException(err)
xcffib.ConnectionException: xcb connection errors because of socket, pipe and other stream errors.
2021-01-26 14:03:58,599 ERROR libqtile manager.py:get_interesting_pid():L631 Got an exception in getting the window pid
Traceback (most recent call last):
  File "/usr/lib/python3.9/site-packages/xcffib/__init__.py", line 571, in wrapper
    return f(*args)
  File "/usr/lib/python3.9/site-packages/xcffib/__init__.py", line 658, in wait_for_reply
    self._process_error(error_p[0])
  File "/usr/lib/python3.9/site-packages/xcffib/__init__.py", line 645, in _process_error
    self.invalid()
  File "/usr/lib/python3.9/site-packages/xcffib/__init__.py", line 559, in invalid
    raise ConnectionException(err)
xcffib.ConnectionException: xcb connection errors because of socket, pipe and other stream errors.

During handling of the above exception, another exception occurred:

Traceback (most recent call last):
  File "/usr/lib/python3.9/site-packages/libqtile/core/manager.py", line 629, in get_interesting_pid
    return win.window.get_net_wm_pid()
  File "/usr/lib/python3.9/site-packages/libqtile/backend/x11/xcbq.py", line 612, in get_net_wm_pid
    r = self.get_property("_NET_WM_PID", unpack=int)
  File "/usr/lib/python3.9/site-packages/libqtile/backend/x11/xcbq.py", line 705, in get_property
    r = self.conn.conn.core.GetProperty(
  File "/usr/lib/python3.9/site-packages/xcffib/__init__.py", line 332, in reply
    data = self.conn.wait_for_reply(self.sequence)
  File "/usr/lib/python3.9/site-packages/xcffib/__init__.py", line 573, in wrapper
    self.invalid()
  File "/usr/lib/python3.9/site-packages/xcffib/__init__.py", line 559, in invalid
    raise ConnectionException(err)
xcffib.ConnectionException: xcb connection errors because of socket, pipe and other stream errors.
2021-01-26 14:03:58,627 ERROR libqtile xcore.py:_xpoll():L269 Shutting down due to X connection error XCB_CONN_ERROR (1)
Traceback (most recent call last):
  File "/usr/lib/python3.9/site-packages/libqtile/backend/x11/xcore.py", line 230, in _xpoll
    event = self.conn.conn.poll_for_event()
  File "/usr/lib/python3.9/site-packages/xcffib/__init__.py", line 569, in wrapper
    self.invalid()
  File "/usr/lib/python3.9/site-packages/xcffib/__init__.py", line 559, in invalid
    raise ConnectionException(err)
xcffib.ConnectionException: xcb connection errors because of socket, pipe and other stream errors.
2021-01-26 14:03:58,628 ERROR libqtile manager.py:get_interesting_pid():L631 Got an exception in getting the window pid
Traceback (most recent call last):
  File "/usr/lib/python3.9/site-packages/libqtile/backend/x11/xcore.py", line 230, in _xpoll
    event = self.conn.conn.poll_for_event()
  File "/usr/lib/python3.9/site-packages/xcffib/__init__.py", line 569, in wrapper
    self.invalid()
  File "/usr/lib/python3.9/site-packages/xcffib/__init__.py", line 559, in invalid
    raise ConnectionException(err)
xcffib.ConnectionException: xcb connection errors because of socket, pipe and other stream errors.

During handling of the above exception, another exception occurred:

Traceback (most recent call last):
  File "/usr/lib/python3.9/site-packages/libqtile/core/manager.py", line 629, in get_interesting_pid
    return win.window.get_net_wm_pid()
  File "/usr/lib/python3.9/site-packages/libqtile/backend/x11/xcbq.py", line 612, in get_net_wm_pid
    r = self.get_property("_NET_WM_PID", unpack=int)
  File "/usr/lib/python3.9/site-packages/libqtile/backend/x11/xcbq.py", line 705, in get_property
    r = self.conn.conn.core.GetProperty(
  File "/usr/lib/python3.9/site-packages/xcffib/xproto.py", line 2720, in GetProperty
    return self.send_request(20, buf, GetPropertyCookie, is_checked=is_checked)
  File "/usr/lib/python3.9/site-packages/xcffib/__init__.py", line 391, in send_request
    seq = self.conn.send_request(flags, xcb_parts + 2, xcb_req)
  File "/usr/lib/python3.9/site-packages/xcffib/__init__.py", line 569, in wrapper
    self.invalid()
  File "/usr/lib/python3.9/site-packages/xcffib/__init__.py", line 559, in invalid
    raise ConnectionException(err)
xcffib.ConnectionException: xcb connection errors because of socket, pipe and other stream errors.
2021-01-26 14:03:58,630 ERROR libqtile manager.py:finalize():L320 exception during finalize
Traceback (most recent call last):
  File "/usr/lib/python3.9/site-packages/libqtile/core/manager.py", line 310, in finalize
    widget.finalize()
  File "/usr/lib/python3.9/site-packages/libqtile/widget/base.py", line 208, in finalize
    self.drawer.finalize()
  File "/usr/lib/python3.9/site-packages/libqtile/drawer.py", line 247, in finalize
    self.qtile.conn.conn.core.FreeGC(self.gc)
  File "/usr/lib/python3.9/site-packages/xcffib/xproto.py", line 3027, in FreeGC
    return self.send_request(60, buf, is_checked=is_checked)
  File "/usr/lib/python3.9/site-packages/xcffib/__init__.py", line 391, in send_request
    seq = self.conn.send_request(flags, xcb_parts + 2, xcb_req)
  File "/usr/lib/python3.9/site-packages/xcffib/__init__.py", line 569, in wrapper
    self.invalid()
  File "/usr/lib/python3.9/site-packages/xcffib/__init__.py", line 559, in invalid
    raise ConnectionException(err)
xcffib.ConnectionException: xcb connection errors because of socket, pipe and other stream errors.
2021-01-26 14:53:39,577 ERROR libqtile xcore.py:_xpoll():L269 Shutting down due to X connection error XCB_CONN_ERROR (1)
Traceback (most recent call last):
  File "/usr/lib/python3.9/site-packages/xcffib/__init__.py", line 571, in wrapper
    return f(*args)
  File "/usr/lib/python3.9/site-packages/xcffib/__init__.py", line 681, in request_check
    self._process_error(err)
  File "/usr/lib/python3.9/site-packages/xcffib/__init__.py", line 645, in _process_error
    self.invalid()
  File "/usr/lib/python3.9/site-packages/xcffib/__init__.py", line 559, in invalid
    raise ConnectionException(err)
xcffib.ConnectionException: xcb connection errors because of socket, pipe and other stream errors.

During handling of the above exception, another exception occurred:

Traceback (most recent call last):
  File "/usr/lib/python3.9/site-packages/libqtile/backend/x11/xcore.py", line 245, in _xpoll
    ret = target(event)
  File "/usr/lib/python3.9/site-packages/libqtile/backend/x11/xcore.py", line 600, in handle_UnmapNotify
    self.qtile.unmap_window(event.window)
  File "/usr/lib/python3.9/site-packages/libqtile/core/manager.py", line 553, in unmap_window
    c.state = window.WithdrawnState
  File "/usr/lib/python3.9/site-packages/libqtile/window.py", line 370, in state
    self.window.set_property('WM_STATE', [val, 0])
  File "/usr/lib/python3.9/site-packages/libqtile/backend/x11/xcbq.py", line 676, in set_property
    self.conn.conn.core.ChangePropertyChecked(
  File "/usr/lib/python3.9/site-packages/xcffib/__init__.py", line 339, in check
    self.conn.request_check(self.sequence)
  File "/usr/lib/python3.9/site-packages/xcffib/__init__.py", line 573, in wrapper
    self.invalid()
  File "/usr/lib/python3.9/site-packages/xcffib/__init__.py", line 559, in invalid
    raise ConnectionException(err)
xcffib.ConnectionException: xcb connection errors because of socket, pipe and other stream errors.
2021-01-26 14:53:39,590 ERROR libqtile manager.py:get_interesting_pid():L631 Got an exception in getting the window pid
Traceback (most recent call last):
  File "/usr/lib/python3.9/site-packages/xcffib/__init__.py", line 571, in wrapper
    return f(*args)
  File "/usr/lib/python3.9/site-packages/xcffib/__init__.py", line 681, in request_check
    self._process_error(err)
  File "/usr/lib/python3.9/site-packages/xcffib/__init__.py", line 645, in _process_error
    self.invalid()
  File "/usr/lib/python3.9/site-packages/xcffib/__init__.py", line 559, in invalid
    raise ConnectionException(err)
xcffib.ConnectionException: xcb connection errors because of socket, pipe and other stream errors.

During handling of the above exception, another exception occurred:

Traceback (most recent call last):
  File "/usr/lib/python3.9/site-packages/libqtile/backend/x11/xcore.py", line 245, in _xpoll
    ret = target(event)
  File "/usr/lib/python3.9/site-packages/libqtile/backend/x11/xcore.py", line 600, in handle_UnmapNotify
    self.qtile.unmap_window(event.window)
  File "/usr/lib/python3.9/site-packages/libqtile/core/manager.py", line 553, in unmap_window
    c.state = window.WithdrawnState
  File "/usr/lib/python3.9/site-packages/libqtile/window.py", line 370, in state
    self.window.set_property('WM_STATE', [val, 0])
  File "/usr/lib/python3.9/site-packages/libqtile/backend/x11/xcbq.py", line 676, in set_property
    self.conn.conn.core.ChangePropertyChecked(
  File "/usr/lib/python3.9/site-packages/xcffib/__init__.py", line 339, in check
    self.conn.request_check(self.sequence)
  File "/usr/lib/python3.9/site-packages/xcffib/__init__.py", line 573, in wrapper
    self.invalid()
  File "/usr/lib/python3.9/site-packages/xcffib/__init__.py", line 559, in invalid
    raise ConnectionException(err)
xcffib.ConnectionException: xcb connection errors because of socket, pipe and other stream errors.

During handling of the above exception, another exception occurred:

Traceback (most recent call last):
  File "/usr/lib/python3.9/site-packages/libqtile/core/manager.py", line 629, in get_interesting_pid
    return win.window.get_net_wm_pid()
  File "/usr/lib/python3.9/site-packages/libqtile/backend/x11/xcbq.py", line 612, in get_net_wm_pid
    r = self.get_property("_NET_WM_PID", unpack=int)
  File "/usr/lib/python3.9/site-packages/libqtile/backend/x11/xcbq.py", line 705, in get_property
    r = self.conn.conn.core.GetProperty(
  File "/usr/lib/python3.9/site-packages/xcffib/xproto.py", line 2720, in GetProperty
    return self.send_request(20, buf, GetPropertyCookie, is_checked=is_checked)
  File "/usr/lib/python3.9/site-packages/xcffib/__init__.py", line 391, in send_request
    seq = self.conn.send_request(flags, xcb_parts + 2, xcb_req)
  File "/usr/lib/python3.9/site-packages/xcffib/__init__.py", line 569, in wrapper
    self.invalid()
  File "/usr/lib/python3.9/site-packages/xcffib/__init__.py", line 559, in invalid
    raise ConnectionException(err)
xcffib.ConnectionException: xcb connection errors because of socket, pipe and other stream errors.
2021-01-26 14:53:39,598 ERROR libqtile manager.py:finalize():L320 exception during finalize
Traceback (most recent call last):
  File "/usr/lib/python3.9/site-packages/libqtile/core/manager.py", line 310, in finalize
    widget.finalize()
  File "/usr/lib/python3.9/site-packages/libqtile/widget/base.py", line 208, in finalize
    self.drawer.finalize()
  File "/usr/lib/python3.9/site-packages/libqtile/drawer.py", line 247, in finalize
    self.qtile.conn.conn.core.FreeGC(self.gc)
  File "/usr/lib/python3.9/site-packages/xcffib/xproto.py", line 3027, in FreeGC
    return self.send_request(60, buf, is_checked=is_checked)
  File "/usr/lib/python3.9/site-packages/xcffib/__init__.py", line 391, in send_request
    seq = self.conn.send_request(flags, xcb_parts + 2, xcb_req)
  File "/usr/lib/python3.9/site-packages/xcffib/__init__.py", line 569, in wrapper
    self.invalid()
  File "/usr/lib/python3.9/site-packages/xcffib/__init__.py", line 559, in invalid
    raise ConnectionException(err)
xcffib.ConnectionException: xcb connection errors because of socket, pipe and other stream errors.
2021-01-27 03:08:12,450 ERROR libqtile manager.py:process_key_event():L375 KB command error kill: No object window in path 'window'
2021-01-27 03:09:40,562 ERROR libqtile xcore.py:_xpoll():L269 Shutting down due to X connection error XCB_CONN_ERROR (1)
Traceback (most recent call last):
  File "/usr/lib/python3.9/site-packages/xcffib/__init__.py", line 571, in wrapper
    return f(*args)
  File "/usr/lib/python3.9/site-packages/xcffib/__init__.py", line 610, in poll_for_event
    self.invalid()
  File "/usr/lib/python3.9/site-packages/xcffib/__init__.py", line 559, in invalid
    raise ConnectionException(err)
xcffib.ConnectionException: xcb connection errors because of socket, pipe and other stream errors.

During handling of the above exception, another exception occurred:

Traceback (most recent call last):
  File "/usr/lib/python3.9/site-packages/libqtile/backend/x11/xcore.py", line 230, in _xpoll
    event = self.conn.conn.poll_for_event()
  File "/usr/lib/python3.9/site-packages/xcffib/__init__.py", line 573, in wrapper
    self.invalid()
  File "/usr/lib/python3.9/site-packages/xcffib/__init__.py", line 559, in invalid
    raise ConnectionException(err)
xcffib.ConnectionException: xcb connection errors because of socket, pipe and other stream errors.
2021-01-27 03:09:40,563 ERROR libqtile manager.py:get_interesting_pid():L631 Got an exception in getting the window pid
Traceback (most recent call last):
  File "/usr/lib/python3.9/site-packages/xcffib/__init__.py", line 571, in wrapper
    return f(*args)
  File "/usr/lib/python3.9/site-packages/xcffib/__init__.py", line 610, in poll_for_event
    self.invalid()
  File "/usr/lib/python3.9/site-packages/xcffib/__init__.py", line 559, in invalid
    raise ConnectionException(err)
xcffib.ConnectionException: xcb connection errors because of socket, pipe and other stream errors.

During handling of the above exception, another exception occurred:

Traceback (most recent call last):
  File "/usr/lib/python3.9/site-packages/libqtile/backend/x11/xcore.py", line 230, in _xpoll
    event = self.conn.conn.poll_for_event()
  File "/usr/lib/python3.9/site-packages/xcffib/__init__.py", line 573, in wrapper
    self.invalid()
  File "/usr/lib/python3.9/site-packages/xcffib/__init__.py", line 559, in invalid
    raise ConnectionException(err)
xcffib.ConnectionException: xcb connection errors because of socket, pipe and other stream errors.

During handling of the above exception, another exception occurred:

Traceback (most recent call last):
  File "/usr/lib/python3.9/site-packages/libqtile/core/manager.py", line 629, in get_interesting_pid
    return win.window.get_net_wm_pid()
  File "/usr/lib/python3.9/site-packages/libqtile/backend/x11/xcbq.py", line 612, in get_net_wm_pid
    r = self.get_property("_NET_WM_PID", unpack=int)
  File "/usr/lib/python3.9/site-packages/libqtile/backend/x11/xcbq.py", line 705, in get_property
    r = self.conn.conn.core.GetProperty(
  File "/usr/lib/python3.9/site-packages/xcffib/xproto.py", line 2720, in GetProperty
    return self.send_request(20, buf, GetPropertyCookie, is_checked=is_checked)
  File "/usr/lib/python3.9/site-packages/xcffib/__init__.py", line 391, in send_request
    seq = self.conn.send_request(flags, xcb_parts + 2, xcb_req)
  File "/usr/lib/python3.9/site-packages/xcffib/__init__.py", line 569, in wrapper
    self.invalid()
  File "/usr/lib/python3.9/site-packages/xcffib/__init__.py", line 559, in invalid
    raise ConnectionException(err)
xcffib.ConnectionException: xcb connection errors because of socket, pipe and other stream errors.
2021-01-27 03:10:49,321 ERROR libqtile manager.py:process_key_event():L375 KB command error kill: No object window in path 'window'
2021-01-27 03:28:17,705 ERROR libqtile xcore.py:_xpoll():L269 Shutting down due to X connection error XCB_CONN_ERROR (1)
Traceback (most recent call last):
  File "/usr/lib/python3.9/site-packages/xcffib/__init__.py", line 571, in wrapper
    return f(*args)
  File "/usr/lib/python3.9/site-packages/xcffib/__init__.py", line 681, in request_check
    self._process_error(err)
  File "/usr/lib/python3.9/site-packages/xcffib/__init__.py", line 645, in _process_error
    self.invalid()
  File "/usr/lib/python3.9/site-packages/xcffib/__init__.py", line 559, in invalid
    raise ConnectionException(err)
xcffib.ConnectionException: xcb connection errors because of socket, pipe and other stream errors.

During handling of the above exception, another exception occurred:

Traceback (most recent call last):
  File "/usr/lib/python3.9/site-packages/libqtile/backend/x11/xcore.py", line 245, in _xpoll
    ret = target(event)
  File "/usr/lib/python3.9/site-packages/libqtile/backend/x11/xcore.py", line 594, in handle_DestroyNotify
    self.qtile.unmanage(event.window)
  File "/usr/lib/python3.9/site-packages/libqtile/core/manager.py", line 612, in unmanage
    self.update_client_list()
  File "/usr/lib/python3.9/site-packages/libqtile/core/manager.py", line 447, in update_client_list
    self.core.update_client_list(windows)
  File "/usr/lib/python3.9/site-packages/libqtile/backend/x11/xcore.py", line 370, in update_client_list
    self._root.set_property("_NET_CLIENT_LIST", windows)
  File "/usr/lib/python3.9/site-packages/libqtile/backend/x11/xcbq.py", line 676, in set_property
    self.conn.conn.core.ChangePropertyChecked(
  File "/usr/lib/python3.9/site-packages/xcffib/__init__.py", line 339, in check
    self.conn.request_check(self.sequence)
  File "/usr/lib/python3.9/site-packages/xcffib/__init__.py", line 573, in wrapper
    self.invalid()
  File "/usr/lib/python3.9/site-packages/xcffib/__init__.py", line 559, in invalid
    raise ConnectionException(err)
xcffib.ConnectionException: xcb connection errors because of socket, pipe and other stream errors.
2021-01-27 03:28:17,707 ERROR libqtile manager.py:get_interesting_pid():L631 Got an exception in getting the window pid
Traceback (most recent call last):
  File "/usr/lib/python3.9/site-packages/xcffib/__init__.py", line 571, in wrapper
    return f(*args)
  File "/usr/lib/python3.9/site-packages/xcffib/__init__.py", line 681, in request_check
    self._process_error(err)
  File "/usr/lib/python3.9/site-packages/xcffib/__init__.py", line 645, in _process_error
    self.invalid()
  File "/usr/lib/python3.9/site-packages/xcffib/__init__.py", line 559, in invalid
    raise ConnectionException(err)
xcffib.ConnectionException: xcb connection errors because of socket, pipe and other stream errors.

During handling of the above exception, another exception occurred:

Traceback (most recent call last):
  File "/usr/lib/python3.9/site-packages/libqtile/backend/x11/xcore.py", line 245, in _xpoll
    ret = target(event)
  File "/usr/lib/python3.9/site-packages/libqtile/backend/x11/xcore.py", line 594, in handle_DestroyNotify
    self.qtile.unmanage(event.window)
  File "/usr/lib/python3.9/site-packages/libqtile/core/manager.py", line 612, in unmanage
    self.update_client_list()
  File "/usr/lib/python3.9/site-packages/libqtile/core/manager.py", line 447, in update_client_list
    self.core.update_client_list(windows)
  File "/usr/lib/python3.9/site-packages/libqtile/backend/x11/xcore.py", line 370, in update_client_list
    self._root.set_property("_NET_CLIENT_LIST", windows)
  File "/usr/lib/python3.9/site-packages/libqtile/backend/x11/xcbq.py", line 676, in set_property
    self.conn.conn.core.ChangePropertyChecked(
  File "/usr/lib/python3.9/site-packages/xcffib/__init__.py", line 339, in check
    self.conn.request_check(self.sequence)
  File "/usr/lib/python3.9/site-packages/xcffib/__init__.py", line 573, in wrapper
    self.invalid()
  File "/usr/lib/python3.9/site-packages/xcffib/__init__.py", line 559, in invalid
    raise ConnectionException(err)
xcffib.ConnectionException: xcb connection errors because of socket, pipe and other stream errors.

During handling of the above exception, another exception occurred:

Traceback (most recent call last):
  File "/usr/lib/python3.9/site-packages/libqtile/core/manager.py", line 629, in get_interesting_pid
    return win.window.get_net_wm_pid()
  File "/usr/lib/python3.9/site-packages/libqtile/backend/x11/xcbq.py", line 612, in get_net_wm_pid
    r = self.get_property("_NET_WM_PID", unpack=int)
  File "/usr/lib/python3.9/site-packages/libqtile/backend/x11/xcbq.py", line 705, in get_property
    r = self.conn.conn.core.GetProperty(
  File "/usr/lib/python3.9/site-packages/xcffib/xproto.py", line 2720, in GetProperty
    return self.send_request(20, buf, GetPropertyCookie, is_checked=is_checked)
  File "/usr/lib/python3.9/site-packages/xcffib/__init__.py", line 391, in send_request
    seq = self.conn.send_request(flags, xcb_parts + 2, xcb_req)
  File "/usr/lib/python3.9/site-packages/xcffib/__init__.py", line 569, in wrapper
    self.invalid()
  File "/usr/lib/python3.9/site-packages/xcffib/__init__.py", line 559, in invalid
    raise ConnectionException(err)
xcffib.ConnectionException: xcb connection errors because of socket, pipe and other stream errors.
2021-01-27 03:28:17,713 ERROR libqtile manager.py:finalize():L320 exception during finalize
Traceback (most recent call last):
  File "/usr/lib/python3.9/site-packages/libqtile/core/manager.py", line 310, in finalize
    widget.finalize()
  File "/usr/lib/python3.9/site-packages/libqtile/widget/base.py", line 208, in finalize
    self.drawer.finalize()
  File "/usr/lib/python3.9/site-packages/libqtile/drawer.py", line 247, in finalize
    self.qtile.conn.conn.core.FreeGC(self.gc)
  File "/usr/lib/python3.9/site-packages/xcffib/xproto.py", line 3027, in FreeGC
    return self.send_request(60, buf, is_checked=is_checked)
  File "/usr/lib/python3.9/site-packages/xcffib/__init__.py", line 391, in send_request
    seq = self.conn.send_request(flags, xcb_parts + 2, xcb_req)
  File "/usr/lib/python3.9/site-packages/xcffib/__init__.py", line 569, in wrapper
    self.invalid()
  File "/usr/lib/python3.9/site-packages/xcffib/__init__.py", line 559, in invalid
    raise ConnectionException(err)
xcffib.ConnectionException: xcb connection errors because of socket, pipe and other stream errors.
2021-01-27 15:27:26,620 ERROR libqtile xcore.py:_xpoll():L269 Shutting down due to X connection error XCB_CONN_ERROR (1)
Traceback (most recent call last):
  File "/usr/lib/python3.9/site-packages/xcffib/__init__.py", line 571, in wrapper
    return f(*args)
  File "/usr/lib/python3.9/site-packages/xcffib/__init__.py", line 610, in poll_for_event
    self.invalid()
  File "/usr/lib/python3.9/site-packages/xcffib/__init__.py", line 559, in invalid
    raise ConnectionException(err)
xcffib.ConnectionException: xcb connection errors because of socket, pipe and other stream errors.

During handling of the above exception, another exception occurred:

Traceback (most recent call last):
  File "/usr/lib/python3.9/site-packages/libqtile/backend/x11/xcore.py", line 230, in _xpoll
    event = self.conn.conn.poll_for_event()
  File "/usr/lib/python3.9/site-packages/xcffib/__init__.py", line 573, in wrapper
    self.invalid()
  File "/usr/lib/python3.9/site-packages/xcffib/__init__.py", line 559, in invalid
    raise ConnectionException(err)
xcffib.ConnectionException: xcb connection errors because of socket, pipe and other stream errors.
2021-01-27 15:27:26,642 ERROR libqtile manager.py:get_interesting_pid():L631 Got an exception in getting the window pid
Traceback (most recent call last):
  File "/usr/lib/python3.9/site-packages/xcffib/__init__.py", line 571, in wrapper
    return f(*args)
  File "/usr/lib/python3.9/site-packages/xcffib/__init__.py", line 610, in poll_for_event
    self.invalid()
  File "/usr/lib/python3.9/site-packages/xcffib/__init__.py", line 559, in invalid
    raise ConnectionException(err)
xcffib.ConnectionException: xcb connection errors because of socket, pipe and other stream errors.

During handling of the above exception, another exception occurred:

Traceback (most recent call last):
  File "/usr/lib/python3.9/site-packages/libqtile/backend/x11/xcore.py", line 230, in _xpoll
    event = self.conn.conn.poll_for_event()
  File "/usr/lib/python3.9/site-packages/xcffib/__init__.py", line 573, in wrapper
    self.invalid()
  File "/usr/lib/python3.9/site-packages/xcffib/__init__.py", line 559, in invalid
    raise ConnectionException(err)
xcffib.ConnectionException: xcb connection errors because of socket, pipe and other stream errors.

During handling of the above exception, another exception occurred:

Traceback (most recent call last):
  File "/usr/lib/python3.9/site-packages/libqtile/core/manager.py", line 629, in get_interesting_pid
    return win.window.get_net_wm_pid()
  File "/usr/lib/python3.9/site-packages/libqtile/backend/x11/xcbq.py", line 612, in get_net_wm_pid
    r = self.get_property("_NET_WM_PID", unpack=int)
  File "/usr/lib/python3.9/site-packages/libqtile/backend/x11/xcbq.py", line 705, in get_property
    r = self.conn.conn.core.GetProperty(
  File "/usr/lib/python3.9/site-packages/xcffib/xproto.py", line 2720, in GetProperty
    return self.send_request(20, buf, GetPropertyCookie, is_checked=is_checked)
  File "/usr/lib/python3.9/site-packages/xcffib/__init__.py", line 391, in send_request
    seq = self.conn.send_request(flags, xcb_parts + 2, xcb_req)
  File "/usr/lib/python3.9/site-packages/xcffib/__init__.py", line 569, in wrapper
    self.invalid()
  File "/usr/lib/python3.9/site-packages/xcffib/__init__.py", line 559, in invalid
    raise ConnectionException(err)
xcffib.ConnectionException: xcb connection errors because of socket, pipe and other stream errors.
2021-01-27 15:27:26,644 ERROR libqtile manager.py:get_interesting_pid():L631 Got an exception in getting the window pid
Traceback (most recent call last):
  File "/usr/lib/python3.9/site-packages/xcffib/__init__.py", line 571, in wrapper
    return f(*args)
  File "/usr/lib/python3.9/site-packages/xcffib/__init__.py", line 610, in poll_for_event
    self.invalid()
  File "/usr/lib/python3.9/site-packages/xcffib/__init__.py", line 559, in invalid
    raise ConnectionException(err)
xcffib.ConnectionException: xcb connection errors because of socket, pipe and other stream errors.

During handling of the above exception, another exception occurred:

Traceback (most recent call last):
  File "/usr/lib/python3.9/site-packages/libqtile/backend/x11/xcore.py", line 230, in _xpoll
    event = self.conn.conn.poll_for_event()
  File "/usr/lib/python3.9/site-packages/xcffib/__init__.py", line 573, in wrapper
    self.invalid()
  File "/usr/lib/python3.9/site-packages/xcffib/__init__.py", line 559, in invalid
    raise ConnectionException(err)
xcffib.ConnectionException: xcb connection errors because of socket, pipe and other stream errors.

During handling of the above exception, another exception occurred:

Traceback (most recent call last):
  File "/usr/lib/python3.9/site-packages/libqtile/core/manager.py", line 629, in get_interesting_pid
    return win.window.get_net_wm_pid()
  File "/usr/lib/python3.9/site-packages/libqtile/backend/x11/xcbq.py", line 612, in get_net_wm_pid
    r = self.get_property("_NET_WM_PID", unpack=int)
  File "/usr/lib/python3.9/site-packages/libqtile/backend/x11/xcbq.py", line 705, in get_property
    r = self.conn.conn.core.GetProperty(
  File "/usr/lib/python3.9/site-packages/xcffib/xproto.py", line 2720, in GetProperty
    return self.send_request(20, buf, GetPropertyCookie, is_checked=is_checked)
  File "/usr/lib/python3.9/site-packages/xcffib/__init__.py", line 391, in send_request
    seq = self.conn.send_request(flags, xcb_parts + 2, xcb_req)
  File "/usr/lib/python3.9/site-packages/xcffib/__init__.py", line 569, in wrapper
    self.invalid()
  File "/usr/lib/python3.9/site-packages/xcffib/__init__.py", line 559, in invalid
    raise ConnectionException(err)
xcffib.ConnectionException: xcb connection errors because of socket, pipe and other stream errors.
2021-01-27 15:27:26,647 ERROR libqtile base.py:_wrapper():L294 got exception from widget timer
Traceback (most recent call last):
  File "/usr/lib/python3.9/site-packages/libqtile/widget/base.py", line 292, in _wrapper
    method(*method_args)
  File "/usr/lib/python3.9/site-packages/libqtile/widget/graph.py", line 182, in update
    self.update_graph()
  File "/usr/lib/python3.9/site-packages/libqtile/widget/graph.py", line 231, in update_graph
    self.push(push_value)
  File "/usr/lib/python3.9/site-packages/libqtile/widget/graph.py", line 174, in push
    self.draw()
  File "/usr/lib/python3.9/site-packages/libqtile/widget/graph.py", line 161, in draw
    self.drawer.draw(offsetx=self.offset, width=self.width)
  File "/usr/lib/python3.9/site-packages/libqtile/drawer.py", line 305, in draw
    self.qtile.conn.conn.core.CopyArea(
  File "/usr/lib/python3.9/site-packages/xcffib/xproto.py", line 3035, in CopyArea
    return self.send_request(62, buf, is_checked=is_checked)
  File "/usr/lib/python3.9/site-packages/xcffib/__init__.py", line 391, in send_request
    seq = self.conn.send_request(flags, xcb_parts + 2, xcb_req)
  File "/usr/lib/python3.9/site-packages/xcffib/__init__.py", line 569, in wrapper
    self.invalid()
  File "/usr/lib/python3.9/site-packages/xcffib/__init__.py", line 559, in invalid
    raise ConnectionException(err)
xcffib.ConnectionException: xcb connection errors because of socket, pipe and other stream errors.
2021-01-27 15:27:26,649 ERROR libqtile base.py:_wrapper():L294 got exception from widget timer
Traceback (most recent call last):
  File "/usr/lib/python3.9/site-packages/libqtile/widget/base.py", line 292, in _wrapper
    method(*method_args)
  File "/usr/lib/python3.9/site-packages/libqtile/widget/base.py", line 457, in timer_setup
    update_interval = self.tick()
  File "/usr/lib/python3.9/site-packages/libqtile/widget/memory.py", line 59, in tick
    self.update(self.poll())
  File "/usr/lib/python3.9/site-packages/libqtile/widget/base.py", line 493, in update
    self.draw()
  File "/usr/lib/python3.9/site-packages/libqtile/widget/base.py", line 416, in draw
    self.drawer.draw(offsetx=self.offsetx, width=self.width)
  File "/usr/lib/python3.9/site-packages/libqtile/drawer.py", line 305, in draw
    self.qtile.conn.conn.core.CopyArea(
  File "/usr/lib/python3.9/site-packages/xcffib/xproto.py", line 3035, in CopyArea
    return self.send_request(62, buf, is_checked=is_checked)
  File "/usr/lib/python3.9/site-packages/xcffib/__init__.py", line 391, in send_request
    seq = self.conn.send_request(flags, xcb_parts + 2, xcb_req)
  File "/usr/lib/python3.9/site-packages/xcffib/__init__.py", line 569, in wrapper
    self.invalid()
  File "/usr/lib/python3.9/site-packages/xcffib/__init__.py", line 559, in invalid
    raise ConnectionException(err)
xcffib.ConnectionException: xcb connection errors because of socket, pipe and other stream errors.
2021-01-27 15:27:26,650 ERROR libqtile manager.py:finalize():L320 exception during finalize
Traceback (most recent call last):
  File "/usr/lib/python3.9/site-packages/libqtile/core/manager.py", line 310, in finalize
    widget.finalize()
  File "/usr/lib/python3.9/site-packages/libqtile/widget/base.py", line 208, in finalize
    self.drawer.finalize()
  File "/usr/lib/python3.9/site-packages/libqtile/drawer.py", line 247, in finalize
    self.qtile.conn.conn.core.FreeGC(self.gc)
  File "/usr/lib/python3.9/site-packages/xcffib/xproto.py", line 3027, in FreeGC
    return self.send_request(60, buf, is_checked=is_checked)
  File "/usr/lib/python3.9/site-packages/xcffib/__init__.py", line 391, in send_request
    seq = self.conn.send_request(flags, xcb_parts + 2, xcb_req)
  File "/usr/lib/python3.9/site-packages/xcffib/__init__.py", line 569, in wrapper
    self.invalid()
  File "/usr/lib/python3.9/site-packages/xcffib/__init__.py", line 559, in invalid
    raise ConnectionException(err)
xcffib.ConnectionException: xcb connection errors because of socket, pipe and other stream errors.
2021-01-27 15:28:43,469 ERROR libqtile xcore.py:_xpoll():L269 Shutting down due to X connection error XCB_CONN_ERROR (1)
Traceback (most recent call last):
  File "/usr/lib/python3.9/site-packages/xcffib/__init__.py", line 571, in wrapper
    return f(*args)
  File "/usr/lib/python3.9/site-packages/xcffib/__init__.py", line 610, in poll_for_event
    self.invalid()
  File "/usr/lib/python3.9/site-packages/xcffib/__init__.py", line 559, in invalid
    raise ConnectionException(err)
xcffib.ConnectionException: xcb connection errors because of socket, pipe and other stream errors.

During handling of the above exception, another exception occurred:

Traceback (most recent call last):
  File "/usr/lib/python3.9/site-packages/libqtile/backend/x11/xcore.py", line 230, in _xpoll
    event = self.conn.conn.poll_for_event()
  File "/usr/lib/python3.9/site-packages/xcffib/__init__.py", line 573, in wrapper
    self.invalid()
  File "/usr/lib/python3.9/site-packages/xcffib/__init__.py", line 559, in invalid
    raise ConnectionException(err)
xcffib.ConnectionException: xcb connection errors because of socket, pipe and other stream errors.
2021-01-27 20:32:00,228 ERROR libqtile xcore.py:_xpoll():L269 Shutting down due to X connection error XCB_CONN_ERROR (1)
Traceback (most recent call last):
  File "/usr/lib/python3.9/site-packages/xcffib/__init__.py", line 571, in wrapper
    return f(*args)
  File "/usr/lib/python3.9/site-packages/xcffib/__init__.py", line 681, in request_check
    self._process_error(err)
  File "/usr/lib/python3.9/site-packages/xcffib/__init__.py", line 645, in _process_error
    self.invalid()
  File "/usr/lib/python3.9/site-packages/xcffib/__init__.py", line 559, in invalid
    raise ConnectionException(err)
xcffib.ConnectionException: xcb connection errors because of socket, pipe and other stream errors.

During handling of the above exception, another exception occurred:

Traceback (most recent call last):
  File "/usr/lib/python3.9/site-packages/libqtile/backend/x11/xcore.py", line 245, in _xpoll
    ret = target(event)
  File "/usr/lib/python3.9/site-packages/libqtile/backend/x11/xcore.py", line 600, in handle_UnmapNotify
    self.qtile.unmap_window(event.window)
  File "/usr/lib/python3.9/site-packages/libqtile/core/manager.py", line 553, in unmap_window
    c.state = window.WithdrawnState
  File "/usr/lib/python3.9/site-packages/libqtile/window.py", line 370, in state
    self.window.set_property('WM_STATE', [val, 0])
  File "/usr/lib/python3.9/site-packages/libqtile/backend/x11/xcbq.py", line 676, in set_property
    self.conn.conn.core.ChangePropertyChecked(
  File "/usr/lib/python3.9/site-packages/xcffib/__init__.py", line 339, in check
    self.conn.request_check(self.sequence)
  File "/usr/lib/python3.9/site-packages/xcffib/__init__.py", line 573, in wrapper
    self.invalid()
  File "/usr/lib/python3.9/site-packages/xcffib/__init__.py", line 559, in invalid
    raise ConnectionException(err)
xcffib.ConnectionException: xcb connection errors because of socket, pipe and other stream errors.
2021-01-27 21:03:16,588 ERROR libqtile xcore.py:_xpoll():L269 Shutting down due to X connection error XCB_CONN_ERROR (1)
Traceback (most recent call last):
  File "/usr/lib/python3.9/site-packages/xcffib/__init__.py", line 571, in wrapper
    return f(*args)
  File "/usr/lib/python3.9/site-packages/xcffib/__init__.py", line 610, in poll_for_event
    self.invalid()
  File "/usr/lib/python3.9/site-packages/xcffib/__init__.py", line 559, in invalid
    raise ConnectionException(err)
xcffib.ConnectionException: xcb connection errors because of socket, pipe and other stream errors.

During handling of the above exception, another exception occurred:

Traceback (most recent call last):
  File "/usr/lib/python3.9/site-packages/libqtile/backend/x11/xcore.py", line 230, in _xpoll
    event = self.conn.conn.poll_for_event()
  File "/usr/lib/python3.9/site-packages/xcffib/__init__.py", line 573, in wrapper
    self.invalid()
  File "/usr/lib/python3.9/site-packages/xcffib/__init__.py", line 559, in invalid
    raise ConnectionException(err)
xcffib.ConnectionException: xcb connection errors because of socket, pipe and other stream errors.
2021-01-27 21:03:16,612 ERROR libqtile manager.py:get_interesting_pid():L631 Got an exception in getting the window pid
Traceback (most recent call last):
  File "/usr/lib/python3.9/site-packages/xcffib/__init__.py", line 571, in wrapper
    return f(*args)
  File "/usr/lib/python3.9/site-packages/xcffib/__init__.py", line 610, in poll_for_event
    self.invalid()
  File "/usr/lib/python3.9/site-packages/xcffib/__init__.py", line 559, in invalid
    raise ConnectionException(err)
xcffib.ConnectionException: xcb connection errors because of socket, pipe and other stream errors.

During handling of the above exception, another exception occurred:

Traceback (most recent call last):
  File "/usr/lib/python3.9/site-packages/libqtile/backend/x11/xcore.py", line 230, in _xpoll
    event = self.conn.conn.poll_for_event()
  File "/usr/lib/python3.9/site-packages/xcffib/__init__.py", line 573, in wrapper
    self.invalid()
  File "/usr/lib/python3.9/site-packages/xcffib/__init__.py", line 559, in invalid
    raise ConnectionException(err)
xcffib.ConnectionException: xcb connection errors because of socket, pipe and other stream errors.

During handling of the above exception, another exception occurred:

Traceback (most recent call last):
  File "/usr/lib/python3.9/site-packages/libqtile/core/manager.py", line 629, in get_interesting_pid
    return win.window.get_net_wm_pid()
  File "/usr/lib/python3.9/site-packages/libqtile/backend/x11/xcbq.py", line 612, in get_net_wm_pid
    r = self.get_property("_NET_WM_PID", unpack=int)
  File "/usr/lib/python3.9/site-packages/libqtile/backend/x11/xcbq.py", line 705, in get_property
    r = self.conn.conn.core.GetProperty(
  File "/usr/lib/python3.9/site-packages/xcffib/xproto.py", line 2720, in GetProperty
    return self.send_request(20, buf, GetPropertyCookie, is_checked=is_checked)
  File "/usr/lib/python3.9/site-packages/xcffib/__init__.py", line 391, in send_request
    seq = self.conn.send_request(flags, xcb_parts + 2, xcb_req)
  File "/usr/lib/python3.9/site-packages/xcffib/__init__.py", line 569, in wrapper
    self.invalid()
  File "/usr/lib/python3.9/site-packages/xcffib/__init__.py", line 559, in invalid
    raise ConnectionException(err)
xcffib.ConnectionException: xcb connection errors because of socket, pipe and other stream errors.
2021-01-27 21:03:16,622 ERROR libqtile manager.py:finalize():L320 exception during finalize
Traceback (most recent call last):
  File "/usr/lib/python3.9/site-packages/libqtile/core/manager.py", line 310, in finalize
    widget.finalize()
  File "/usr/lib/python3.9/site-packages/libqtile/widget/base.py", line 208, in finalize
    self.drawer.finalize()
  File "/usr/lib/python3.9/site-packages/libqtile/drawer.py", line 247, in finalize
    self.qtile.conn.conn.core.FreeGC(self.gc)
  File "/usr/lib/python3.9/site-packages/xcffib/xproto.py", line 3027, in FreeGC
    return self.send_request(60, buf, is_checked=is_checked)
  File "/usr/lib/python3.9/site-packages/xcffib/__init__.py", line 391, in send_request
    seq = self.conn.send_request(flags, xcb_parts + 2, xcb_req)
  File "/usr/lib/python3.9/site-packages/xcffib/__init__.py", line 569, in wrapper
    self.invalid()
  File "/usr/lib/python3.9/site-packages/xcffib/__init__.py", line 559, in invalid
    raise ConnectionException(err)
xcffib.ConnectionException: xcb connection errors because of socket, pipe and other stream errors.
2021-01-27 21:22:34,045 ERROR libqtile xcore.py:_xpoll():L269 Shutting down due to X connection error XCB_CONN_ERROR (1)
Traceback (most recent call last):
  File "/usr/lib/python3.9/site-packages/xcffib/__init__.py", line 571, in wrapper
    return f(*args)
  File "/usr/lib/python3.9/site-packages/xcffib/__init__.py", line 610, in poll_for_event
    self.invalid()
  File "/usr/lib/python3.9/site-packages/xcffib/__init__.py", line 559, in invalid
    raise ConnectionException(err)
xcffib.ConnectionException: xcb connection errors because of socket, pipe and other stream errors.

During handling of the above exception, another exception occurred:

Traceback (most recent call last):
  File "/usr/lib/python3.9/site-packages/libqtile/backend/x11/xcore.py", line 230, in _xpoll
    event = self.conn.conn.poll_for_event()
  File "/usr/lib/python3.9/site-packages/xcffib/__init__.py", line 573, in wrapper
    self.invalid()
  File "/usr/lib/python3.9/site-packages/xcffib/__init__.py", line 559, in invalid
    raise ConnectionException(err)
xcffib.ConnectionException: xcb connection errors because of socket, pipe and other stream errors.
2021-01-27 21:22:34,092 ERROR libqtile manager.py:get_interesting_pid():L631 Got an exception in getting the window pid
Traceback (most recent call last):
  File "/usr/lib/python3.9/site-packages/xcffib/__init__.py", line 571, in wrapper
    return f(*args)
  File "/usr/lib/python3.9/site-packages/xcffib/__init__.py", line 610, in poll_for_event
    self.invalid()
  File "/usr/lib/python3.9/site-packages/xcffib/__init__.py", line 559, in invalid
    raise ConnectionException(err)
xcffib.ConnectionException: xcb connection errors because of socket, pipe and other stream errors.

During handling of the above exception, another exception occurred:

Traceback (most recent call last):
  File "/usr/lib/python3.9/site-packages/libqtile/backend/x11/xcore.py", line 230, in _xpoll
    event = self.conn.conn.poll_for_event()
  File "/usr/lib/python3.9/site-packages/xcffib/__init__.py", line 573, in wrapper
    self.invalid()
  File "/usr/lib/python3.9/site-packages/xcffib/__init__.py", line 559, in invalid
    raise ConnectionException(err)
xcffib.ConnectionException: xcb connection errors because of socket, pipe and other stream errors.

During handling of the above exception, another exception occurred:

Traceback (most recent call last):
  File "/usr/lib/python3.9/site-packages/libqtile/core/manager.py", line 629, in get_interesting_pid
    return win.window.get_net_wm_pid()
  File "/usr/lib/python3.9/site-packages/libqtile/backend/x11/xcbq.py", line 612, in get_net_wm_pid
    r = self.get_property("_NET_WM_PID", unpack=int)
  File "/usr/lib/python3.9/site-packages/libqtile/backend/x11/xcbq.py", line 705, in get_property
    r = self.conn.conn.core.GetProperty(
  File "/usr/lib/python3.9/site-packages/xcffib/xproto.py", line 2720, in GetProperty
    return self.send_request(20, buf, GetPropertyCookie, is_checked=is_checked)
  File "/usr/lib/python3.9/site-packages/xcffib/__init__.py", line 391, in send_request
    seq = self.conn.send_request(flags, xcb_parts + 2, xcb_req)
  File "/usr/lib/python3.9/site-packages/xcffib/__init__.py", line 569, in wrapper
    self.invalid()
  File "/usr/lib/python3.9/site-packages/xcffib/__init__.py", line 559, in invalid
    raise ConnectionException(err)
xcffib.ConnectionException: xcb connection errors because of socket, pipe and other stream errors.
2021-01-27 21:22:34,095 ERROR libqtile manager.py:get_interesting_pid():L631 Got an exception in getting the window pid
Traceback (most recent call last):
  File "/usr/lib/python3.9/site-packages/xcffib/__init__.py", line 571, in wrapper
    return f(*args)
  File "/usr/lib/python3.9/site-packages/xcffib/__init__.py", line 610, in poll_for_event
    self.invalid()
  File "/usr/lib/python3.9/site-packages/xcffib/__init__.py", line 559, in invalid
    raise ConnectionException(err)
xcffib.ConnectionException: xcb connection errors because of socket, pipe and other stream errors.

During handling of the above exception, another exception occurred:

Traceback (most recent call last):
  File "/usr/lib/python3.9/site-packages/libqtile/backend/x11/xcore.py", line 230, in _xpoll
    event = self.conn.conn.poll_for_event()
  File "/usr/lib/python3.9/site-packages/xcffib/__init__.py", line 573, in wrapper
    self.invalid()
  File "/usr/lib/python3.9/site-packages/xcffib/__init__.py", line 559, in invalid
    raise ConnectionException(err)
xcffib.ConnectionException: xcb connection errors because of socket, pipe and other stream errors.

During handling of the above exception, another exception occurred:

Traceback (most recent call last):
  File "/usr/lib/python3.9/site-packages/libqtile/core/manager.py", line 629, in get_interesting_pid
    return win.window.get_net_wm_pid()
  File "/usr/lib/python3.9/site-packages/libqtile/backend/x11/xcbq.py", line 612, in get_net_wm_pid
    r = self.get_property("_NET_WM_PID", unpack=int)
  File "/usr/lib/python3.9/site-packages/libqtile/backend/x11/xcbq.py", line 705, in get_property
    r = self.conn.conn.core.GetProperty(
  File "/usr/lib/python3.9/site-packages/xcffib/xproto.py", line 2720, in GetProperty
    return self.send_request(20, buf, GetPropertyCookie, is_checked=is_checked)
  File "/usr/lib/python3.9/site-packages/xcffib/__init__.py", line 391, in send_request
    seq = self.conn.send_request(flags, xcb_parts + 2, xcb_req)
  File "/usr/lib/python3.9/site-packages/xcffib/__init__.py", line 569, in wrapper
    self.invalid()
  File "/usr/lib/python3.9/site-packages/xcffib/__init__.py", line 559, in invalid
    raise ConnectionException(err)
xcffib.ConnectionException: xcb connection errors because of socket, pipe and other stream errors.
2021-01-27 21:22:34,097 ERROR libqtile manager.py:finalize():L320 exception during finalize
Traceback (most recent call last):
  File "/usr/lib/python3.9/site-packages/libqtile/core/manager.py", line 310, in finalize
    widget.finalize()
  File "/usr/lib/python3.9/site-packages/libqtile/widget/base.py", line 208, in finalize
    self.drawer.finalize()
  File "/usr/lib/python3.9/site-packages/libqtile/drawer.py", line 247, in finalize
    self.qtile.conn.conn.core.FreeGC(self.gc)
  File "/usr/lib/python3.9/site-packages/xcffib/xproto.py", line 3027, in FreeGC
    return self.send_request(60, buf, is_checked=is_checked)
  File "/usr/lib/python3.9/site-packages/xcffib/__init__.py", line 391, in send_request
    seq = self.conn.send_request(flags, xcb_parts + 2, xcb_req)
  File "/usr/lib/python3.9/site-packages/xcffib/__init__.py", line 569, in wrapper
    self.invalid()
  File "/usr/lib/python3.9/site-packages/xcffib/__init__.py", line 559, in invalid
    raise ConnectionException(err)
xcffib.ConnectionException: xcb connection errors because of socket, pipe and other stream errors.
2021-01-27 21:29:53,159 ERROR libqtile xcore.py:_xpoll():L269 Shutting down due to X connection error XCB_CONN_ERROR (1)
Traceback (most recent call last):
  File "/usr/lib/python3.9/site-packages/xcffib/__init__.py", line 571, in wrapper
    return f(*args)
  File "/usr/lib/python3.9/site-packages/xcffib/__init__.py", line 681, in request_check
    self._process_error(err)
  File "/usr/lib/python3.9/site-packages/xcffib/__init__.py", line 645, in _process_error
    self.invalid()
  File "/usr/lib/python3.9/site-packages/xcffib/__init__.py", line 559, in invalid
    raise ConnectionException(err)
xcffib.ConnectionException: xcb connection errors because of socket, pipe and other stream errors.

During handling of the above exception, another exception occurred:

Traceback (most recent call last):
  File "/usr/lib/python3.9/site-packages/libqtile/backend/x11/xcore.py", line 245, in _xpoll
    ret = target(event)
  File "/usr/lib/python3.9/site-packages/libqtile/backend/x11/xcore.py", line 600, in handle_UnmapNotify
    self.qtile.unmap_window(event.window)
  File "/usr/lib/python3.9/site-packages/libqtile/core/manager.py", line 553, in unmap_window
    c.state = window.WithdrawnState
  File "/usr/lib/python3.9/site-packages/libqtile/window.py", line 370, in state
    self.window.set_property('WM_STATE', [val, 0])
  File "/usr/lib/python3.9/site-packages/libqtile/backend/x11/xcbq.py", line 676, in set_property
    self.conn.conn.core.ChangePropertyChecked(
  File "/usr/lib/python3.9/site-packages/xcffib/__init__.py", line 339, in check
    self.conn.request_check(self.sequence)
  File "/usr/lib/python3.9/site-packages/xcffib/__init__.py", line 573, in wrapper
    self.invalid()
  File "/usr/lib/python3.9/site-packages/xcffib/__init__.py", line 559, in invalid
    raise ConnectionException(err)
xcffib.ConnectionException: xcb connection errors because of socket, pipe and other stream errors.
2021-01-27 21:29:53,193 ERROR libqtile manager.py:get_interesting_pid():L631 Got an exception in getting the window pid
Traceback (most recent call last):
  File "/usr/lib/python3.9/site-packages/xcffib/__init__.py", line 571, in wrapper
    return f(*args)
  File "/usr/lib/python3.9/site-packages/xcffib/__init__.py", line 681, in request_check
    self._process_error(err)
  File "/usr/lib/python3.9/site-packages/xcffib/__init__.py", line 645, in _process_error
    self.invalid()
  File "/usr/lib/python3.9/site-packages/xcffib/__init__.py", line 559, in invalid
    raise ConnectionException(err)
xcffib.ConnectionException: xcb connection errors because of socket, pipe and other stream errors.

During handling of the above exception, another exception occurred:

Traceback (most recent call last):
  File "/usr/lib/python3.9/site-packages/libqtile/backend/x11/xcore.py", line 245, in _xpoll
    ret = target(event)
  File "/usr/lib/python3.9/site-packages/libqtile/backend/x11/xcore.py", line 600, in handle_UnmapNotify
    self.qtile.unmap_window(event.window)
  File "/usr/lib/python3.9/site-packages/libqtile/core/manager.py", line 553, in unmap_window
    c.state = window.WithdrawnState
  File "/usr/lib/python3.9/site-packages/libqtile/window.py", line 370, in state
    self.window.set_property('WM_STATE', [val, 0])
  File "/usr/lib/python3.9/site-packages/libqtile/backend/x11/xcbq.py", line 676, in set_property
    self.conn.conn.core.ChangePropertyChecked(
  File "/usr/lib/python3.9/site-packages/xcffib/__init__.py", line 339, in check
    self.conn.request_check(self.sequence)
  File "/usr/lib/python3.9/site-packages/xcffib/__init__.py", line 573, in wrapper
    self.invalid()
  File "/usr/lib/python3.9/site-packages/xcffib/__init__.py", line 559, in invalid
    raise ConnectionException(err)
xcffib.ConnectionException: xcb connection errors because of socket, pipe and other stream errors.

During handling of the above exception, another exception occurred:

Traceback (most recent call last):
  File "/usr/lib/python3.9/site-packages/libqtile/core/manager.py", line 629, in get_interesting_pid
    return win.window.get_net_wm_pid()
  File "/usr/lib/python3.9/site-packages/libqtile/backend/x11/xcbq.py", line 612, in get_net_wm_pid
    r = self.get_property("_NET_WM_PID", unpack=int)
  File "/usr/lib/python3.9/site-packages/libqtile/backend/x11/xcbq.py", line 705, in get_property
    r = self.conn.conn.core.GetProperty(
  File "/usr/lib/python3.9/site-packages/xcffib/xproto.py", line 2720, in GetProperty
    return self.send_request(20, buf, GetPropertyCookie, is_checked=is_checked)
  File "/usr/lib/python3.9/site-packages/xcffib/__init__.py", line 391, in send_request
    seq = self.conn.send_request(flags, xcb_parts + 2, xcb_req)
  File "/usr/lib/python3.9/site-packages/xcffib/__init__.py", line 569, in wrapper
    self.invalid()
  File "/usr/lib/python3.9/site-packages/xcffib/__init__.py", line 559, in invalid
    raise ConnectionException(err)
xcffib.ConnectionException: xcb connection errors because of socket, pipe and other stream errors.
2021-01-27 21:29:53,195 ERROR libqtile manager.py:finalize():L320 exception during finalize
Traceback (most recent call last):
  File "/usr/lib/python3.9/site-packages/libqtile/core/manager.py", line 310, in finalize
    widget.finalize()
  File "/usr/lib/python3.9/site-packages/libqtile/widget/base.py", line 208, in finalize
    self.drawer.finalize()
  File "/usr/lib/python3.9/site-packages/libqtile/drawer.py", line 247, in finalize
    self.qtile.conn.conn.core.FreeGC(self.gc)
  File "/usr/lib/python3.9/site-packages/xcffib/xproto.py", line 3027, in FreeGC
    return self.send_request(60, buf, is_checked=is_checked)
  File "/usr/lib/python3.9/site-packages/xcffib/__init__.py", line 391, in send_request
    seq = self.conn.send_request(flags, xcb_parts + 2, xcb_req)
  File "/usr/lib/python3.9/site-packages/xcffib/__init__.py", line 569, in wrapper
    self.invalid()
  File "/usr/lib/python3.9/site-packages/xcffib/__init__.py", line 559, in invalid
    raise ConnectionException(err)
xcffib.ConnectionException: xcb connection errors because of socket, pipe and other stream errors.
2021-01-27 22:29:16,633 ERROR libqtile xcore.py:_xpoll():L269 Shutting down due to X connection error XCB_CONN_ERROR (1)
Traceback (most recent call last):
  File "/usr/lib/python3.9/site-packages/xcffib/__init__.py", line 571, in wrapper
    return f(*args)
  File "/usr/lib/python3.9/site-packages/xcffib/__init__.py", line 681, in request_check
    self._process_error(err)
  File "/usr/lib/python3.9/site-packages/xcffib/__init__.py", line 645, in _process_error
    self.invalid()
  File "/usr/lib/python3.9/site-packages/xcffib/__init__.py", line 559, in invalid
    raise ConnectionException(err)
xcffib.ConnectionException: xcb connection errors because of socket, pipe and other stream errors.

During handling of the above exception, another exception occurred:

Traceback (most recent call last):
  File "/usr/lib/python3.9/site-packages/libqtile/backend/x11/xcore.py", line 245, in _xpoll
    ret = target(event)
  File "/usr/lib/python3.9/site-packages/libqtile/backend/x11/xcore.py", line 600, in handle_UnmapNotify
    self.qtile.unmap_window(event.window)
  File "/usr/lib/python3.9/site-packages/libqtile/core/manager.py", line 553, in unmap_window
    c.state = window.WithdrawnState
  File "/usr/lib/python3.9/site-packages/libqtile/window.py", line 370, in state
    self.window.set_property('WM_STATE', [val, 0])
  File "/usr/lib/python3.9/site-packages/libqtile/backend/x11/xcbq.py", line 676, in set_property
    self.conn.conn.core.ChangePropertyChecked(
  File "/usr/lib/python3.9/site-packages/xcffib/__init__.py", line 339, in check
    self.conn.request_check(self.sequence)
  File "/usr/lib/python3.9/site-packages/xcffib/__init__.py", line 573, in wrapper
    self.invalid()
  File "/usr/lib/python3.9/site-packages/xcffib/__init__.py", line 559, in invalid
    raise ConnectionException(err)
xcffib.ConnectionException: xcb connection errors because of socket, pipe and other stream errors.
2021-01-27 22:30:49,910 ERROR libqtile xcore.py:_xpoll():L269 Shutting down due to X connection error XCB_CONN_ERROR (1)
Traceback (most recent call last):
  File "/usr/lib/python3.9/site-packages/xcffib/__init__.py", line 571, in wrapper
    return f(*args)
  File "/usr/lib/python3.9/site-packages/xcffib/__init__.py", line 681, in request_check
    self._process_error(err)
  File "/usr/lib/python3.9/site-packages/xcffib/__init__.py", line 645, in _process_error
    self.invalid()
  File "/usr/lib/python3.9/site-packages/xcffib/__init__.py", line 559, in invalid
    raise ConnectionException(err)
xcffib.ConnectionException: xcb connection errors because of socket, pipe and other stream errors.

During handling of the above exception, another exception occurred:

Traceback (most recent call last):
  File "/usr/lib/python3.9/site-packages/libqtile/backend/x11/xcore.py", line 245, in _xpoll
    ret = target(event)
  File "/usr/lib/python3.9/site-packages/libqtile/backend/x11/xcore.py", line 600, in handle_UnmapNotify
    self.qtile.unmap_window(event.window)
  File "/usr/lib/python3.9/site-packages/libqtile/core/manager.py", line 553, in unmap_window
    c.state = window.WithdrawnState
  File "/usr/lib/python3.9/site-packages/libqtile/window.py", line 370, in state
    self.window.set_property('WM_STATE', [val, 0])
  File "/usr/lib/python3.9/site-packages/libqtile/backend/x11/xcbq.py", line 676, in set_property
    self.conn.conn.core.ChangePropertyChecked(
  File "/usr/lib/python3.9/site-packages/xcffib/__init__.py", line 339, in check
    self.conn.request_check(self.sequence)
  File "/usr/lib/python3.9/site-packages/xcffib/__init__.py", line 573, in wrapper
    self.invalid()
  File "/usr/lib/python3.9/site-packages/xcffib/__init__.py", line 559, in invalid
    raise ConnectionException(err)
xcffib.ConnectionException: xcb connection errors because of socket, pipe and other s2021-01-28 00:48:53,191 ERROR libqtile manager.py:get_interesting_pid():L631 Got an exception in getting the window pid
Traceback (most recent call last):
  File "/usr/lib/python3.9/site-packages/xcffib/__init__.py", line 571, in wrapper
    return f(*args)
  File "/usr/lib/python3.9/site-packages/xcffib/__init__.py", line 658, in wait_for_reply
    self._process_error(error_p[0])
  File "/usr/lib/python3.9/site-packages/xcffib/__init__.py", line 645, in _process_error
    self.invalid()
  File "/usr/lib/python3.9/site-packages/xcffib/__init__.py", line 559, in invalid
    raise ConnectionException(err)
xcffib.ConnectionException: xcb connection errors because of socket, pipe and other stream errors.

During handling of the above exception, another exception occurred:

Traceback (most recent call last):
  File "/usr/lib/python3.9/site-packages/libqtile/core/manager.py", line 629, in get_interesting_pid
    return win.window.get_net_wm_pid()
  File "/usr/lib/python3.9/site-packages/libqtile/backend/x11/xcbq.py", line 612, in get_net_wm_pid
    r = self.get_property("_NET_WM_PID", unpack=int)
  File "/usr/lib/python3.9/site-packages/libqtile/backend/x11/xcbq.py", line 705, in get_property
    r = self.conn.conn.core.GetProperty(
  File "/usr/lib/python3.9/site-packages/xcffib/__init__.py", line 332, in reply
    data = self.conn.wait_for_reply(self.sequence)
  File "/usr/lib/python3.9/site-packages/xcffib/__init__.py", line 573, in wrapper
    self.invalid()
  File "/usr/lib/python3.9/site-packages/xcffib/__init__.py", line 559, in invalid
    raise ConnectionException(err)
xcffib.ConnectionException: xcb connection errors because of socket, pipe and other stream errors.
2021-01-28 00:48:53,205 ERROR libqtile manager.py:get_interesting_pid():L631 Got an exception in getting the window pid
Traceback (most recent call last):
  File "/usr/lib/python3.9/site-packages/libqtile/core/manager.py", line 629, in get_interesting_pid
    return win.window.get_net_wm_pid()
  File "/usr/lib/python3.9/site-packages/libqtile/backend/x11/xcbq.py", line 612, in get_net_wm_pid
    r = self.get_property("_NET_WM_PID", unpack=int)
  File "/usr/lib/python3.9/site-packages/libqtile/backend/x11/xcbq.py", line 705, in get_property
    r = self.conn.conn.core.GetProperty(
  File "/usr/lib/python3.9/site-packages/xcffib/xproto.py", line 2720, in GetProperty
    return self.send_request(20, buf, GetPropertyCookie, is_checked=is_checked)
  File "/usr/lib/python3.9/site-packages/xcffib/__init__.py", line 391, in send_request
    seq = self.conn.send_request(flags, xcb_parts + 2, xcb_req)
  File "/usr/lib/python3.9/site-packages/xcffib/__init__.py", line 569, in wrapper
    self.invalid()
  File "/usr/lib/python3.9/site-packages/xcffib/__init__.py", line 559, in invalid
    raise ConnectionException(err)
xcffib.ConnectionException: xcb connection errors because of socket, pipe and other stream errors.
2021-01-28 00:48:53,207 ERROR libqtile xcore.py:_xpoll():L269 Shutting down due to X connection error XCB_CONN_ERROR (1)
Traceback (most recent call last):
  File "/usr/lib/python3.9/site-packages/libqtile/backend/x11/xcore.py", line 230, in _xpoll
    event = self.conn.conn.poll_for_event()
  File "/usr/lib/python3.9/site-packages/xcffib/__init__.py", line 569, in wrapper
    self.invalid()
  File "/usr/lib/python3.9/site-packages/xcffib/__init__.py", line 559, in invalid
    raise ConnectionException(err)
xcffib.ConnectionException: xcb connection errors because of socket, pipe and other stream errors.
2021-01-28 00:48:53,208 ERROR libqtile manager.py:get_interesting_pid():L631 Got an exception in getting the window pid
Traceback (most recent call last):
  File "/usr/lib/python3.9/site-packages/libqtile/backend/x11/xcore.py", line 230, in _xpoll
    event = self.conn.conn.poll_for_event()
  File "/usr/lib/python3.9/site-packages/xcffib/__init__.py", line 569, in wrapper
    self.invalid()
  File "/usr/lib/python3.9/site-packages/xcffib/__init__.py", line 559, in invalid
    raise ConnectionException(err)
xcffib.ConnectionException: xcb connection errors because of socket, pipe and other stream errors.

During handling of the above exception, another exception occurred:

Traceback (most recent call last):
  File "/usr/lib/python3.9/site-packages/libqtile/core/manager.py", line 629, in get_interesting_pid
    return win.window.get_net_wm_pid()
  File "/usr/lib/python3.9/site-packages/libqtile/backend/x11/xcbq.py", line 612, in get_net_wm_pid
    r = self.get_property("_NET_WM_PID", unpack=int)
  File "/usr/lib/python3.9/site-packages/libqtile/backend/x11/xcbq.py", line 705, in get_property
    r = self.conn.conn.core.GetProperty(
  File "/usr/lib/python3.9/site-packages/xcffib/xproto.py", line 2720, in GetProperty
    return self.send_request(20, buf, GetPropertyCookie, is_checked=is_checked)
  File "/usr/lib/python3.9/site-packages/xcffib/__init__.py", line 391, in send_request
    seq = self.conn.send_request(flags, xcb_parts + 2, xcb_req)
  File "/usr/lib/python3.9/site-packages/xcffib/__init__.py", line 569, in wrapper
    self.invalid()
  File "/usr/lib/python3.9/site-packages/xcffib/__init__.py", line 559, in invalid
    raise ConnectionException(err)
xcffib.ConnectionException: xcb connection errors because of socket, pipe and other stream errors.
2021-01-28 00:48:53,208 ERROR libqtile manager.py:get_interesting_pid():L631 Got an exception in getting the window pid
Traceback (most recent call last):
  File "/usr/lib/python3.9/site-packages/libqtile/backend/x11/xcore.py", line 230, in _xpoll
    event = self.conn.conn.poll_for_event()
  File "/usr/lib/python3.9/site-packages/xcffib/__init__.py", line 569, in wrapper
    self.invalid()
  File "/usr/lib/python3.9/site-packages/xcffib/__init__.py", line 559, in invalid
    raise ConnectionException(err)
xcffib.ConnectionException: xcb connection errors because of socket, pipe and other stream errors.

During handling of the above exception, another exception occurred:

Traceback (most recent call last):
  File "/usr/lib/python3.9/site-packages/libqtile/core/manager.py", line 629, in get_interesting_pid
    return win.window.get_net_wm_pid()
  File "/usr/lib/python3.9/site-packages/libqtile/backend/x11/xcbq.py", line 612, in get_net_wm_pid
    r = self.get_property("_NET_WM_PID", unpack=int)
  File "/usr/lib/python3.9/site-packages/libqtile/backend/x11/xcbq.py", line 705, in get_property
    r = self.conn.conn.core.GetProperty(
  File "/usr/lib/python3.9/site-packages/xcffib/xproto.py", line 2720, in GetProperty
    return self.send_request(20, buf, GetPropertyCookie, is_checked=is_checked)
  File "/usr/lib/python3.9/site-packages/xcffib/__init__.py", line 391, in send_request
    seq = self.conn.send_request(flags, xcb_parts + 2, xcb_req)
  File "/usr/lib/python3.9/site-packages/xcffib/__init__.py", line 569, in wrapper
    self.invalid()
  File "/usr/lib/python3.9/site-packages/xcffib/__init__.py", line 559, in invalid
    raise ConnectionException(err)
xcffib.ConnectionException: xcb connection errors because of socket, pipe and other stream errors.
2021-01-28 00:48:53,209 ERROR libqtile manager.py:finalize():L320 exception during finalize
Traceback (most recent call last):
  File "/usr/lib/python3.9/site-packages/libqtile/core/manager.py", line 310, in finalize
    widget.finalize()
  File "/usr/lib/python3.9/site-packages/libqtile/widget/base.py", line 208, in finalize
    self.drawer.finalize()
  File "/usr/lib/python3.9/site-packages/libqtile/drawer.py", line 247, in finalize
    self.qtile.conn.conn.core.FreeGC(self.gc)
  File "/usr/lib/python3.9/site-packages/xcffib/xproto.py", line 3027, in FreeGC
    return self.send_request(60, buf, is_checked=is_checked)
  File "/usr/lib/python3.9/site-packages/xcffib/__init__.py", line 391, in send_request
    seq = self.conn.send_request(flags, xcb_parts + 2, xcb_req)
  File "/usr/lib/python3.9/site-packages/xcffib/__init__.py", line 569, in wrapper
    self.invalid()
  File "/usr/lib/python3.9/site-packages/xcffib/__init__.py", line 559, in invalid
    raise ConnectionException(err)
xcffib.ConnectionException: xcb connection errors because of socket, pipe and other stream errors.
2021-01-31 06:06:36,736 ERROR libqtile xcore.py:_xpoll():L269 Shutting down due to X connection error XCB_CONN_ERROR (1)
Traceback (most recent call last):
  File "/usr/lib/python3.9/site-packages/xcffib/__init__.py", line 571, in wrapper
    return f(*args)
  File "/usr/lib/python3.9/site-packages/xcffib/__init__.py", line 610, in poll_for_event
    self.invalid()
  File "/usr/lib/python3.9/site-packages/xcffib/__init__.py", line 559, in invalid
    raise ConnectionException(err)
xcffib.ConnectionException: xcb connection errors because of socket, pipe and other stream errors.

During handling of the above exception, another exception occurred:

Traceback (most recent call last):
  File "/usr/lib/python3.9/site-packages/libqtile/backend/x11/xcore.py", line 230, in _xpoll
    event = self.conn.conn.poll_for_event()
  File "/usr/lib/python3.9/site-packages/xcffib/__init__.py", line 573, in wrapper
    self.invalid()
  File "/usr/lib/python3.9/site-packages/xcffib/__init__.py", line 559, in invalid
    raise ConnectionException(err)
xcffib.ConnectionException: xcb connection errors because of socket, pipe and other stream errors.
2021-01-31 06:06:36,931 ERROR libqtile manager.py:get_interesting_pid():L631 Got an exception in getting the window pid
Traceback (most recent call last):
  File "/usr/lib/python3.9/site-packages/xcffib/__init__.py", line 571, in wrapper
    return f(*args)
  File "/usr/lib/python3.9/site-packages/xcffib/__init__.py", line 610, in poll_for_event
    self.invalid()
  File "/usr/lib/python3.9/site-packages/xcffib/__init__.py", line 559, in invalid
    raise ConnectionException(err)
xcffib.ConnectionException: xcb connection errors because of socket, pipe and other stream errors.

During handling of the above exception, another exception occurred:

Traceback (most recent call last):
  File "/usr/lib/python3.9/site-packages/libqtile/backend/x11/xcore.py", line 230, in _xpoll
    event = self.conn.conn.poll_for_event()
  File "/usr/lib/python3.9/site-packages/xcffib/__init__.py", line 573, in wrapper
    self.invalid()
  File "/usr/lib/python3.9/site-packages/xcffib/__init__.py", line 559, in invalid
    raise ConnectionException(err)
xcffib.ConnectionException: xcb connection errors because of socket, pipe and other stream errors.

During handling of the above exception, another exception occurred:

Traceback (most recent call last):
  File "/usr/lib/python3.9/site-packages/libqtile/core/manager.py", line 629, in get_interesting_pid
    return win.window.get_net_wm_pid()
  File "/usr/lib/python3.9/site-packages/libqtile/backend/x11/xcbq.py", line 612, in get_net_wm_pid
    r = self.get_property("_NET_WM_PID", unpack=int)
  File "/usr/lib/python3.9/site-packages/libqtile/backend/x11/xcbq.py", line 705, in get_property
    r = self.conn.conn.core.GetProperty(
  File "/usr/lib/python3.9/site-packages/xcffib/xproto.py", line 2720, in GetProperty
    return self.send_request(20, buf, GetPropertyCookie, is_checked=is_checked)
  File "/usr/lib/python3.9/site-packages/xcffib/__init__.py", line 391, in send_request
    seq = self.conn.send_request(flags, xcb_parts + 2, xcb_req)
  File "/usr/lib/python3.9/site-packages/xcffib/__init__.py", line 569, in wrapper
    self.invalid()
  File "/usr/lib/python3.9/site-packages/xcffib/__init__.py", line 559, in invalid
    raise ConnectionException(err)
xcffib.ConnectionException: xcb connection errors because of socket, pipe and other stream errors.
2021-01-31 06:06:36,987 ERROR libqtile manager.py:finalize():L320 exception during finalize
Traceback (most recent call last):
  File "/usr/lib/python3.9/site-packages/libqtile/core/manager.py", line 310, in finalize
    widget.finalize()
  File "/usr/lib/python3.9/site-packages/libqtile/widget/base.py", line 208, in finalize
    self.drawer.finalize()
  File "/usr/lib/python3.9/site-packages/libqtile/drawer.py", line 247, in finalize
    self.qtile.conn.conn.core.FreeGC(self.gc)
  File "/usr/lib/python3.9/site-packages/xcffib/xproto.py", line 3027, in FreeGC
    return self.send_request(60, buf, is_checked=is_checked)
  File "/usr/lib/python3.9/site-packages/xcffib/__init__.py", line 391, in send_request
    seq = self.conn.send_request(flags, xcb_parts + 2, xcb_req)
  File "/usr/lib/python3.9/site-packages/xcffib/__init__.py", line 569, in wrapper
    self.invalid()
  File "/usr/lib/python3.9/site-packages/xcffib/__init__.py", line 559, in invalid
    raise ConnectionException(err)
xcffib.ConnectionException: xcb connection errors because of socket, pipe and other stream errors.
2021-01-31 06:13:02,319 ERROR libqtile manager.py:handle_exception():L77 xcb connection errors because of socket, pipe and other stream errors.
Traceback (most recent call last):
  File "/usr/lib/python3.9/asyncio/events.py", line 80, in _run
    self._context.run(self._callback, *self._args)
  File "/usr/lib/python3.9/site-packages/libqtile/core/manager.py", line 928, in f
    self.conn.flush()
  File "/usr/lib/python3.9/site-packages/libqtile/backend/x11/xcbq.py", line 899, in flush
    return self.conn.flush()
  File "/usr/lib/python3.9/site-packages/xcffib/__init__.py", line 573, in wrapper
    self.invalid()
  File "/usr/lib/python3.9/site-packages/xcffib/__init__.py", line 559, in invalid
    raise ConnectionException(err)
xcffib.ConnectionException: xcb connection errors because of socket, pipe and other stream errors.
2021-01-31 06:13:02,557 ERROR libqtile base.py:_wrapper():L294 got exception from widget timer
Traceback (most recent call last):
  File "/usr/lib/python3.9/site-packages/libqtile/widget/base.py", line 292, in _wrapper
    method(*method_args)
  File "/usr/lib/python3.9/site-packages/libqtile/widget/base.py", line 457, in timer_setup
    update_interval = self.tick()
  File "/usr/lib/python3.9/site-packages/libqtile/widget/memory.py", line 59, in tick
    self.update(self.poll())
  File "/usr/lib/python3.9/site-packages/libqtile/widget/base.py", line 493, in update
    self.draw()
  File "/usr/lib/python3.9/site-packages/libqtile/widget/base.py", line 416, in draw
    self.drawer.draw(offsetx=self.offsetx, width=self.width)
  File "/usr/lib/python3.9/site-packages/libqtile/drawer.py", line 305, in draw
    self.qtile.conn.conn.core.CopyArea(
  File "/usr/lib/python3.9/site-packages/xcffib/xproto.py", line 3035, in CopyArea
    return self.send_request(62, buf, is_checked=is_checked)
  File "/usr/lib/python3.9/site-packages/xcffib/__init__.py", line 391, in send_request
    seq = self.conn.send_request(flags, xcb_parts + 2, xcb_req)
  File "/usr/lib/python3.9/site-packages/xcffib/__init__.py", line 569, in wrapper
    self.invalid()
  File "/usr/lib/python3.9/site-packages/xcffib/__init__.py", line 559, in invalid
    raise ConnectionException(err)
xcffib.ConnectionException: xcb connection errors because of socket, pipe and other stream errors.
2021-01-31 06:13:02,558 ERROR libqtile manager.py:handle_exception():L77 xcb connection errors because of socket, pipe and other stream errors.
Traceback (most recent call last):
  File "/usr/lib/python3.9/asyncio/events.py", line 80, in _run
    self._context.run(self._callback, *self._args)
  File "/usr/lib/python3.9/site-packages/libqtile/core/manager.py", line 928, in f
    self.conn.flush()
  File "/usr/lib/python3.9/site-packages/libqtile/backend/x11/xcbq.py", line 899, in flush
    return self.conn.flush()
  File "/usr/lib/python3.9/site-packages/xcffib/__init__.py", line 569, in wrapper
    self.invalid()
  File "/usr/lib/python3.9/site-packages/xcffib/__init__.py", line 559, in invalid
    raise ConnectionException(err)
xcffib.ConnectionException: xcb connection errors because of socket, pipe and other stream errors.
2021-01-31 06:13:02,558 ERROR libqtile xcore.py:_xpoll():L269 Shutting down due to X connection error XCB_CONN_ERROR (1)
Traceback (most recent call last):
  File "/usr/lib/python3.9/site-packages/libqtile/backend/x11/xcore.py", line 230, in _xpoll
    event = self.conn.conn.poll_for_event()
  File "/usr/lib/python3.9/site-packages/xcffib/__init__.py", line 569, in wrapper
    self.invalid()
  File "/usr/lib/python3.9/site-packages/xcffib/__init__.py", line 559, in invalid
    raise ConnectionException(err)
xcffib.ConnectionException: xcb connection errors because of socket, pipe and other stream errors.
2021-01-31 06:13:02,559 ERROR libqtile manager.py:get_interesting_pid():L631 Got an exception in getting the window pid
Traceback (most recent call last):
  File "/usr/lib/python3.9/site-packages/libqtile/backend/x11/xcore.py", line 230, in _xpoll
    event = self.conn.conn.poll_for_event()
  File "/usr/lib/python3.9/site-packages/xcffib/__init__.py", line 569, in wrapper
    self.invalid()
  File "/usr/lib/python3.9/site-packages/xcffib/__init__.py", line 559, in invalid
    raise ConnectionException(err)
xcffib.ConnectionException: xcb connection errors because of socket, pipe and other stream errors.

During handling of the above exception, another exception occurred:

Traceback (most recent call last):
  File "/usr/lib/python3.9/site-packages/libqtile/core/manager.py", line 629, in get_interesting_pid
    return win.window.get_net_wm_pid()
  File "/usr/lib/python3.9/site-packages/libqtile/backend/x11/xcbq.py", line 612, in get_net_wm_pid
    r = self.get_property("_NET_WM_PID", unpack=int)
  File "/usr/lib/python3.9/site-packages/libqtile/backend/x11/xcbq.py", line 705, in get_property
    r = self.conn.conn.core.GetProperty(
  File "/usr/lib/python3.9/site-packages/xcffib/xproto.py", line 2720, in GetProperty
    return self.send_request(20, buf, GetPropertyCookie, is_checked=is_checked)
  File "/usr/lib/python3.9/site-packages/xcffib/__init__.py", line 391, in send_request
    seq = self.conn.send_request(flags, xcb_parts + 2, xcb_req)
  File "/usr/lib/python3.9/site-packages/xcffib/__init__.py", line 569, in wrapper
    self.invalid()
  File "/usr/lib/python3.9/site-packages/xcffib/__init__.py", line 559, in invalid
    raise ConnectionException(err)
xcffib.ConnectionException: xcb connection errors because of socket, pipe and other stream errors.
2021-01-31 06:13:02,561 ERROR libqtile manager.py:get_interesting_pid():L631 Got an exception in getting the window pid
Traceback (most recent call last):
  File "/usr/lib/python3.9/site-packages/libqtile/core/manager.py", line 629, in get_interesting_pid
    return win.window.get_net_wm_pid()
  File "/usr/lib/python3.9/site-packages/libqtile/backend/x11/xcbq.py", line 612, in get_net_wm_pid
    r = self.get_property("_NET_WM_PID", unpack=int)
  File "/usr/lib/python3.9/site-packages/libqtile/backend/x11/xcbq.py", line 705, in get_property
    r = self.conn.conn.core.GetProperty(
  File "/usr/lib/python3.9/site-packages/xcffib/xproto.py", line 2720, in GetProperty
    return self.send_request(20, buf, GetPropertyCookie, is_checked=is_checked)
  File "/usr/lib/python3.9/site-packages/xcffib/__init__.py", line 391, in send_request
    seq = self.conn.send_request(flags, xcb_parts + 2, xcb_req)
  File "/usr/lib/python3.9/site-packages/xcffib/__init__.py", line 569, in wrapper
    self.invalid()
  File "/usr/lib/python3.9/site-packages/xcffib/__init__.py", line 559, in invalid
    raise ConnectionException(err)
xcffib.ConnectionException: xcb connection errors because of socket, pipe and other stream errors.
2021-01-31 06:13:02,561 ERROR libqtile manager.py:get_interesting_pid():L631 Got an exception in getting the window pid
Traceback (most recent call last):
  File "/usr/lib/python3.9/site-packages/libqtile/core/manager.py", line 629, in get_interesting_pid
    return win.window.get_net_wm_pid()
  File "/usr/lib/python3.9/site-packages/libqtile/backend/x11/xcbq.py", line 612, in get_net_wm_pid
    r = self.get_property("_NET_WM_PID", unpack=int)
  File "/usr/lib/python3.9/site-packages/libqtile/backend/x11/xcbq.py", line 705, in get_property
    r = self.conn.conn.core.GetProperty(
  File "/usr/lib/python3.9/site-packages/xcffib/xproto.py", line 2720, in GetProperty
    return self.send_request(20, buf, GetPropertyCookie, is_checked=is_checked)
  File "/usr/lib/python3.9/site-packages/xcffib/__init__.py", line 391, in send_request
    seq = self.conn.send_request(flags, xcb_parts + 2, xcb_req)
  File "/usr/lib/python3.9/site-packages/xcffib/__init__.py", line 569, in wrapper
    self.invalid()
  File "/usr/lib/python3.9/site-packages/xcffib/__init__.py", line 559, in invalid
    raise ConnectionException(err)
xcffib.ConnectionException: xcb connection errors because of socket, pipe and other stream errors.
2021-01-31 06:13:02,561 ERROR libqtile manager.py:finalize():L320 exception during finalize
Traceback (most recent call last):
  File "/usr/lib/python3.9/site-packages/libqtile/core/manager.py", line 310, in finalize
    widget.finalize()
  File "/usr/lib/python3.9/site-packages/libqtile/widget/base.py", line 208, in finalize
    self.drawer.finalize()
  File "/usr/lib/python3.9/site-packages/libqtile/drawer.py", line 247, in finalize
    self.qtile.conn.conn.core.FreeGC(self.gc)
  File "/usr/lib/python3.9/site-packages/xcffib/xproto.py", line 3027, in FreeGC
    return self.send_request(60, buf, is_checked=is_checked)
  File "/usr/lib/python3.9/site-packages/xcffib/__init__.py", line 391, in send_request
    seq = self.conn.send_request(flags, xcb_parts + 2, xcb_req)
  File "/usr/lib/python3.9/site-packages/xcffib/__init__.py", line 569, in wrapper
    self.invalid()
  File "/usr/lib/python3.9/site-packages/xcffib/__init__.py", line 559, in invalid
    raise ConnectionException(err)
xcffib.ConnectionException: xcb connection errors because of socket, pipe and other stream errors.
2021-02-02 23:20:12,143 ERROR libqtile xcore.py:_xpoll():L269 Shutting down due to X connection error XCB_CONN_ERROR (1)
Traceback (most recent call last):
  File "/usr/lib/python3.9/site-packages/xcffib/__init__.py", line 571, in wrapper
    return f(*args)
  File "/usr/lib/python3.9/site-packages/xcffib/__init__.py", line 610, in poll_for_event
    self.invalid()
  File "/usr/lib/python3.9/site-packages/xcffib/__init__.py", line 559, in invalid
    raise ConnectionException(err)
xcffib.ConnectionException: xcb connection errors because of socket, pipe and other stream errors.

During handling of the above exception, another exception occurred:

Traceback (most recent call last):
  File "/usr/lib/python3.9/site-packages/libqtile/backend/x11/xcore.py", line 230, in _xpoll
    event = self.conn.conn.poll_for_event()
  File "/usr/lib/python3.9/site-packages/xcffib/__init__.py", line 573, in wrapper
    self.invalid()
  File "/usr/lib/python3.9/site-packages/xcffib/__init__.py", line 559, in invalid
    raise ConnectionException(err)
xcffib.ConnectionException: xcb connection errors because of socket, pipe and other stream errors.
2021-02-02 23:20:12,192 ERROR libqtile manager.py:get_interesting_pid():L631 Got an exception in getting the window pid
Traceback (most recent call last):
  File "/usr/lib/python3.9/site-packages/xcffib/__init__.py", line 571, in wrapper
    return f(*args)
  File "/usr/lib/python3.9/site-packages/xcffib/__init__.py", line 610, in poll_for_event
    self.invalid()
  File "/usr/lib/python3.9/site-packages/xcffib/__init__.py", line 559, in invalid
    raise ConnectionException(err)
xcffib.ConnectionException: xcb connection errors because of socket, pipe and other stream errors.

During handling of the above exception, another exception occurred:

Traceback (most recent call last):
  File "/usr/lib/python3.9/site-packages/libqtile/backend/x11/xcore.py", line 230, in _xpoll
    event = self.conn.conn.poll_for_event()
  File "/usr/lib/python3.9/site-packages/xcffib/__init__.py", line 573, in wrapper
    self.invalid()
  File "/usr/lib/python3.9/site-packages/xcffib/__init__.py", line 559, in invalid
    raise ConnectionException(err)
xcffib.ConnectionException: xcb connection errors because of socket, pipe and other stream errors.

During handling of the above exception, another exception occurred:

Traceback (most recent call last):
  File "/usr/lib/python3.9/site-packages/libqtile/core/manager.py", line 629, in get_interesting_pid
    return win.window.get_net_wm_pid()
  File "/usr/lib/python3.9/site-packages/libqtile/backend/x11/xcbq.py", line 612, in get_net_wm_pid
    r = self.get_property("_NET_WM_PID", unpack=int)
  File "/usr/lib/python3.9/site-packages/libqtile/backend/x11/xcbq.py", line 705, in get_property
    r = self.conn.conn.core.GetProperty(
  File "/usr/lib/python3.9/site-packages/xcffib/xproto.py", line 2720, in GetProperty
    return self.send_request(20, buf, GetPropertyCookie, is_checked=is_checked)
  File "/usr/lib/python3.9/site-packages/xcffib/__init__.py", line 391, in send_request
    seq = self.conn.send_request(flags, xcb_parts + 2, xcb_req)
  File "/usr/lib/python3.9/site-packages/xcffib/__init__.py", line 569, in wrapper
    self.invalid()
  File "/usr/lib/python3.9/site-packages/xcffib/__init__.py", line 559, in invalid
    raise ConnectionException(err)
xcffib.ConnectionException: xcb connection errors because of socket, pipe and other stream errors.
2021-02-02 23:20:12,197 ERROR libqtile manager.py:get_interesting_pid():L631 Got an exception in getting the window pid
Traceback (most recent call last):
  File "/usr/lib/python3.9/site-packages/xcffib/__init__.py", line 571, in wrapper
    return f(*args)
  File "/usr/lib/python3.9/site-packages/xcffib/__init__.py", line 610, in poll_for_event
    self.invalid()
  File "/usr/lib/python3.9/site-packages/xcffib/__init__.py", line 559, in invalid
    raise ConnectionException(err)
xcffib.ConnectionException: xcb connection errors because of socket, pipe and other stream errors.

During handling of the above exception, another exception occurred:

Traceback (most recent call last):
  File "/usr/lib/python3.9/site-packages/libqtile/backend/x11/xcore.py", line 230, in _xpoll
    event = self.conn.conn.poll_for_event()
  File "/usr/lib/python3.9/site-packages/xcffib/__init__.py", line 573, in wrapper
    self.invalid()
  File "/usr/lib/python3.9/site-packages/xcffib/__init__.py", line 559, in invalid
    raise ConnectionException(err)
xcffib.ConnectionException: xcb connection errors because of socket, pipe and other stream errors.

During handling of the above exception, another exception occurred:

Traceback (most recent call last):
  File "/usr/lib/python3.9/site-packages/libqtile/core/manager.py", line 629, in get_interesting_pid
    return win.window.get_net_wm_pid()
  File "/usr/lib/python3.9/site-packages/libqtile/backend/x11/xcbq.py", line 612, in get_net_wm_pid
    r = self.get_property("_NET_WM_PID", unpack=int)
  File "/usr/lib/python3.9/site-packages/libqtile/backend/x11/xcbq.py", line 705, in get_property
    r = self.conn.conn.core.GetProperty(
  File "/usr/lib/python3.9/site-packages/xcffib/xproto.py", line 2720, in GetProperty
    return self.send_request(20, buf, GetPropertyCookie, is_checked=is_checked)
  File "/usr/lib/python3.9/site-packages/xcffib/__init__.py", line 391, in send_request
    seq = self.conn.send_request(flags, xcb_parts + 2, xcb_req)
  File "/usr/lib/python3.9/site-packages/xcffib/__init__.py", line 569, in wrapper
    self.invalid()
  File "/usr/lib/python3.9/site-packages/xcffib/__init__.py", line 559, in invalid
    raise ConnectionException(err)
xcffib.ConnectionException: xcb connection errors because of socket, pipe and other stream errors.
2021-02-02 23:20:12,199 ERROR libqtile manager.py:finalize():L320 exception during finalize
Traceback (most recent call last):
  File "/usr/lib/python3.9/site-packages/libqtile/core/manager.py", line 310, in finalize
    widget.finalize()
  File "/usr/lib/python3.9/site-packages/libqtile/widget/base.py", line 208, in finalize
    self.drawer.finalize()
  File "/usr/lib/python3.9/site-packages/libqtile/drawer.py", line 247, in finalize
    self.qtile.conn.conn.core.FreeGC(self.gc)
  File "/usr/lib/python3.9/site-packages/xcffib/xproto.py", line 3027, in FreeGC
    return self.send_request(60, buf, is_checked=is_checked)
  File "/usr/lib/python3.9/site-packages/xcffib/__init__.py", line 391, in send_request
    seq = self.conn.send_request(flags, xcb_parts + 2, xcb_req)
  File "/usr/lib/python3.9/site-packages/xcffib/__init__.py", line 569, in wrapper
    self.invalid()
  File "/usr/lib/python3.9/site-packages/xcffib/__init__.py", line 559, in invalid
    raise ConnectionException(err)
xcffib.ConnectionException: xcb connection errors because of socket, pipe and other stream errors.
2021-02-02 23:52:17,370 ERROR libqtile manager.py:process_key_event():L375 KB command error kill: No object window in path 'window'
2021-02-02 23:52:23,870 ERROR libqtile xcore.py:_xpoll():L269 Shutting down due to X connection error XCB_CONN_ERROR (1)
Traceback (most recent call last):
  File "/usr/lib/python3.9/site-packages/xcffib/__init__.py", line 571, in wrapper
    return f(*args)
  File "/usr/lib/python3.9/site-packages/xcffib/__init__.py", line 610, in poll_for_event
    self.invalid()
  File "/usr/lib/python3.9/site-packages/xcffib/__init__.py", line 559, in invalid
    raise ConnectionException(err)
xcffib.ConnectionException: xcb connection errors because of socket, pipe and other stream errors.

During handling of the above exception, another exception occurred:

Traceback (most recent call last):
  File "/usr/lib/python3.9/site-packages/libqtile/backend/x11/xcore.py", line 230, in _xpoll
    event = self.conn.conn.poll_for_event()
  File "/usr/lib/python3.9/site-packages/xcffib/__init__.py", line 573, in wrapper
    self.invalid()
  File "/usr/lib/python3.9/site-packages/xcffib/__init__.py", line 559, in invalid
    raise ConnectionException(err)
xcffib.ConnectionException: xcb connection errors because of socket, pipe and other stream errors.
2021-02-02 23:52:23,872 ERROR libqtile manager.py:get_interesting_pid():L631 Got an exception in getting the window pid
Traceback (most recent call last):
  File "/usr/lib/python3.9/site-packages/xcffib/__init__.py", line 571, in wrapper
    return f(*args)
  File "/usr/lib/python3.9/site-packages/xcffib/__init__.py", line 610, in poll_for_event
    self.invalid()
  File "/usr/lib/python3.9/site-packages/xcffib/__init__.py", line 559, in invalid
    raise ConnectionException(err)
xcffib.ConnectionException: xcb connection errors because of socket, pipe and other stream errors.

During handling of the above exception, another exception occurred:

Traceback (most recent call last):
  File "/usr/lib/python3.9/site-packages/libqtile/backend/x11/xcore.py", line 230, in _xpoll
    event = self.conn.conn.poll_for_event()
  File "/usr/lib/python3.9/site-packages/xcffib/__init__.py", line 573, in wrapper
    self.invalid()
  File "/usr/lib/python3.9/site-packages/xcffib/__init__.py", line 559, in invalid
    raise ConnectionException(err)
xcffib.ConnectionException: xcb connection errors because of socket, pipe and other stream errors.

During handling of the above exception, another exception occurred:

Traceback (most recent call last):
  File "/usr/lib/python3.9/site-packages/libqtile/core/manager.py", line 629, in get_interesting_pid
    return win.window.get_net_wm_pid()
  File "/usr/lib/python3.9/site-packages/libqtile/backend/x11/xcbq.py", line 612, in get_net_wm_pid
    r = self.get_property("_NET_WM_PID", unpack=int)
  File "/usr/lib/python3.9/site-packages/libqtile/backend/x11/xcbq.py", line 705, in get_property
    r = self.conn.conn.core.GetProperty(
  File "/usr/lib/python3.9/site-packages/xcffib/xproto.py", line 2720, in GetProperty
    return self.send_request(20, buf, GetPropertyCookie, is_checked=is_checked)
  File "/usr/lib/python3.9/site-packages/xcffib/__init__.py", line 391, in send_request
    seq = self.conn.send_request(flags, xcb_parts + 2, xcb_req)
  File "/usr/lib/python3.9/site-packages/xcffib/__init__.py", line 569, in wrapper
    self.invalid()
  File "/usr/lib/python3.9/site-packages/xcffib/__init__.py", line 559, in invalid
    raise ConnectionException(err)
xcffib.ConnectionException: xcb connection errors because of socket, pipe and other stream errors.
2021-02-02 23:52:23,877 ERROR libqtile manager.py:finalize():L320 exception during finalize
Traceback (most recent call last):
  File "/usr/lib/python3.9/site-packages/libqtile/core/manager.py", line 310, in finalize
    widget.finalize()
  File "/usr/lib/python3.9/site-packages/libqtile/widget/base.py", line 208, in finalize
    self.drawer.finalize()
  File "/usr/lib/python3.9/site-packages/libqtile/drawer.py", line 247, in finalize
    self.qtile.conn.conn.core.FreeGC(self.gc)
  File "/usr/lib/python3.9/site-packages/xcffib/xproto.py", line 3027, in FreeGC
    return self.send_request(60, buf, is_checked=is_checked)
  File "/usr/lib/python3.9/site-packages/xcffib/__init__.py", line 391, in send_request
    seq = self.conn.send_request(flags, xcb_parts + 2, xcb_req)
  File "/usr/lib/python3.9/site-packages/xcffib/__init__.py", line 569, in wrapper
    self.invalid()
  File "/usr/lib/python3.9/site-packages/xcffib/__init__.py", line 559, in invalid
    raise ConnectionException(err)
xcffib.ConnectionException: xcb connection errors because of socket, pipe and other stream errors.
2021-02-03 02:51:59,853 ERROR libqtile manager.py:get_interesting_pid():L631 Got an exception in getting the window pid
Traceback (most recent call last):
  File "/usr/lib/python3.9/site-packages/xcffib/__init__.py", line 571, in wrapper
    return f(*args)
  File "/usr/lib/python3.9/site-packages/xcffib/__init__.py", line 658, in wait_for_reply
    self._process_error(error_p[0])
  File "/usr/lib/python3.9/site-packages/xcffib/__init__.py", line 645, in _process_error
    self.invalid()
  File "/usr/lib/python3.9/site-packages/xcffib/__init__.py", line 559, in invalid
    raise ConnectionException(err)
xcffib.ConnectionException: xcb connection errors because of socket, pipe and other stream errors.

During handling of the above exception, another exception occurred:

Traceback (most recent call last):
  File "/usr/lib/python3.9/site-packages/libqtile/core/manager.py", line 629, in get_interesting_pid
    return win.window.get_net_wm_pid()
  File "/usr/lib/python3.9/site-packages/libqtile/backend/x11/xcbq.py", line 612, in get_net_wm_pid
    r = self.get_property("_NET_WM_PID", unpack=int)
  File "/usr/lib/python3.9/site-packages/libqtile/backend/x11/xcbq.py", line 705, in get_property
    r = self.conn.conn.core.GetProperty(
  File "/usr/lib/python3.9/site-packages/xcffib/__init__.py", line 332, in reply
    data = self.conn.wait_for_reply(self.sequence)
  File "/usr/lib/python3.9/site-packages/xcffib/__init__.py", line 573, in wrapper
    self.invalid()
  File "/usr/lib/python3.9/site-packages/xcffib/__init__.py", line 559, in invalid
    raise ConnectionException(err)
xcffib.ConnectionException: xcb connection errors because of socket, pipe and other stream errors.
2021-02-03 02:52:00,158 ERROR libqtile xcore.py:_xpoll():L269 Shutting down due to X connection error XCB_CONN_ERROR (1)
Traceback (most recent call last):
  File "/usr/lib/python3.9/site-packages/libqtile/backend/x11/xcore.py", line 230, in _xpoll
    event = self.conn.conn.poll_for_event()
  File "/usr/lib/python3.9/site-packages/xcffib/__init__.py", line 569, in wrapper
    self.invalid()
  File "/usr/lib/python3.9/site-packages/xcffib/__init__.py", line 559, in invalid
    raise ConnectionException(err)
xcffib.ConnectionException: xcb connection errors because of socket, pipe and other stream errors.
2021-02-03 02:52:00,170 ERROR libqtile manager.py:get_interesting_pid():L631 Got an exception in getting the window pid
Traceback (most recent call last):
  File "/usr/lib/python3.9/site-packages/libqtile/backend/x11/xcore.py", line 230, in _xpoll
    event = self.conn.conn.poll_for_event()
  File "/usr/lib/python3.9/site-packages/xcffib/__init__.py", line 569, in wrapper
    self.invalid()
  File "/usr/lib/python3.9/site-packages/xcffib/__init__.py", line 559, in invalid
    raise ConnectionException(err)
xcffib.ConnectionException: xcb connection errors because of socket, pipe and other stream errors.

During handling of the above exception, another exception occurred:

Traceback (most recent call last):
  File "/usr/lib/python3.9/site-packages/libqtile/core/manager.py", line 629, in get_interesting_pid
    return win.window.get_net_wm_pid()
  File "/usr/lib/python3.9/site-packages/libqtile/backend/x11/xcbq.py", line 612, in get_net_wm_pid
    r = self.get_property("_NET_WM_PID", unpack=int)
  File "/usr/lib/python3.9/site-packages/libqtile/backend/x11/xcbq.py", line 705, in get_property
    r = self.conn.conn.core.GetProperty(
  File "/usr/lib/python3.9/site-packages/xcffib/xproto.py", line 2720, in GetProperty
    return self.send_request(20, buf, GetPropertyCookie, is_checked=is_checked)
  File "/usr/lib/python3.9/site-packages/xcffib/__init__.py", line 391, in send_request
    seq = self.conn.send_request(flags, xcb_parts + 2, xcb_req)
  File "/usr/lib/python3.9/site-packages/xcffib/__init__.py", line 569, in wrapper
    self.invalid()
  File "/usr/lib/python3.9/site-packages/xcffib/__init__.py", line 559, in invalid
    raise ConnectionException(err)
xcffib.ConnectionException: xcb connection errors because of socket, pipe and other stream errors.
2021-02-03 02:52:00,172 ERROR libqtile base.py:_wrapper():L294 got exception from widget timer
Traceback (most recent call last):
  File "/usr/lib/python3.9/site-packages/libqtile/widget/base.py", line 292, in _wrapper
    method(*method_args)
  File "/usr/lib/python3.9/site-packages/libqtile/widget/base.py", line 457, in timer_setup
    update_interval = self.tick()
  File "/usr/lib/python3.9/site-packages/libqtile/widget/clock.py", line 73, in tick
    self.update(self.poll())
  File "/usr/lib/python3.9/site-packages/libqtile/widget/base.py", line 493, in update
    self.draw()
  File "/usr/lib/python3.9/site-packages/libqtile/widget/base.py", line 416, in draw
    self.drawer.draw(offsetx=self.offsetx, width=self.width)
  File "/usr/lib/python3.9/site-packages/libqtile/drawer.py", line 305, in draw
    self.qtile.conn.conn.core.CopyArea(
  File "/usr/lib/python3.9/site-packages/xcffib/xproto.py", line 3035, in CopyArea
    return self.send_request(62, buf, is_checked=is_checked)
  File "/usr/lib/python3.9/site-packages/xcffib/__init__.py", line 391, in send_request
    seq = self.conn.send_request(flags, xcb_parts + 2, xcb_req)
  File "/usr/lib/python3.9/site-packages/xcffib/__init__.py", line 569, in wrapper
    self.invalid()
  File "/usr/lib/python3.9/site-packages/xcffib/__init__.py", line 559, in invalid
    raise ConnectionException(err)
xcffib.ConnectionException: xcb connection errors because of socket, pipe and other stream errors.
2021-02-03 02:52:00,221 ERROR libqtile manager.py:finalize():L320 exception during finalize
Traceback (most recent call last):
  File "/usr/lib/python3.9/site-packages/libqtile/core/manager.py", line 310, in finalize
    widget.finalize()
  File "/usr/lib/python3.9/site-packages/libqtile/widget/base.py", line 208, in finalize
    self.drawer.finalize()
  File "/usr/lib/python3.9/site-packages/libqtile/drawer.py", line 247, in finalize
    self.qtile.conn.conn.core.FreeGC(self.gc)
  File "/usr/lib/python3.9/site-packages/xcffib/xproto.py", line 3027, in FreeGC
    return self.send_request(60, buf, is_checked=is_checked)
  File "/usr/lib/python3.9/site-packages/xcffib/__init__.py", line 391, in send_request
    seq = self.conn.send_request(flags, xcb_parts + 2, xcb_req)
  File "/usr/lib/python3.9/site-packages/xcffib/__init__.py", line 569, in wrapper
    self.invalid()
  File "/usr/lib/python3.9/site-packages/xcffib/__init__.py", line 559, in invalid
    raise ConnectionException(err)
xcffib.ConnectionException: xcb connection errors because of socket, pipe and other stream errors.
2021-02-03 15:56:18,282 ERROR libqtile xcore.py:_xpoll():L269 Shutting down due to X connection error XCB_CONN_ERROR (1)
Traceback (most recent call last):
  File "/usr/lib/python3.9/site-packages/xcffib/__init__.py", line 571, in wrapper
    return f(*args)
  File "/usr/lib/python3.9/site-packages/xcffib/__init__.py", line 610, in poll_for_event
    self.invalid()
  File "/usr/lib/python3.9/site-packages/xcffib/__init__.py", line 559, in invalid
    raise ConnectionException(err)
xcffib.ConnectionException: xcb connection errors because of socket, pipe and other stream errors.

During handling of the above exception, another exception occurred:

Traceback (most recent call last):
  File "/usr/lib/python3.9/site-packages/libqtile/backend/x11/xcore.py", line 230, in _xpoll
    event = self.conn.conn.poll_for_event()
  File "/usr/lib/python3.9/site-packages/xcffib/__init__.py", line 573, in wrapper
    self.invalid()
  File "/usr/lib/python3.9/site-packages/xcffib/__init__.py", line 559, in invalid
    raise ConnectionException(err)
xcffib.ConnectionException: xcb connection errors because of socket, pipe and other stream errors.
2021-02-03 15:56:18,355 ERROR libqtile manager.py:get_interesting_pid():L631 Got an exception in getting the window pid
Traceback (most recent call last):
  File "/usr/lib/python3.9/site-packages/xcffib/__init__.py", line 571, in wrapper
    return f(*args)
  File "/usr/lib/python3.9/site-packages/xcffib/__init__.py", line 610, in poll_for_event
    self.invalid()
  File "/usr/lib/python3.9/site-packages/xcffib/__init__.py", line 559, in invalid
    raise ConnectionException(err)
xcffib.ConnectionException: xcb connection errors because of socket, pipe and other stream errors.

During handling of the above exception, another exception occurred:

Traceback (most recent call last):
  File "/usr/lib/python3.9/site-packages/libqtile/backend/x11/xcore.py", line 230, in _xpoll
    event = self.conn.conn.poll_for_event()
  File "/usr/lib/python3.9/site-packages/xcffib/__init__.py", line 573, in wrapper
    self.invalid()
  File "/usr/lib/python3.9/site-packages/xcffib/__init__.py", line 559, in invalid
    raise ConnectionException(err)
xcffib.ConnectionException: xcb connection errors because of socket, pipe and other stream errors.

During handling of the above exception, another exception occurred:

Traceback (most recent call last):
  File "/usr/lib/python3.9/site-packages/libqtile/core/manager.py", line 629, in get_interesting_pid
    return win.window.get_net_wm_pid()
  File "/usr/lib/python3.9/site-packages/libqtile/backend/x11/xcbq.py", line 612, in get_net_wm_pid
    r = self.get_property("_NET_WM_PID", unpack=int)
  File "/usr/lib/python3.9/site-packages/libqtile/backend/x11/xcbq.py", line 705, in get_property
    r = self.conn.conn.core.GetProperty(
  File "/usr/lib/python3.9/site-packages/xcffib/xproto.py", line 2720, in GetProperty
    return self.send_request(20, buf, GetPropertyCookie, is_checked=is_checked)
  File "/usr/lib/python3.9/site-packages/xcffib/__init__.py", line 391, in send_request
    seq = self.conn.send_request(flags, xcb_parts + 2, xcb_req)
  File "/usr/lib/python3.9/site-packages/xcffib/__init__.py", line 569, in wrapper
    self.invalid()
  File "/usr/lib/python3.9/site-packages/xcffib/__init__.py", line 559, in invalid
    raise ConnectionException(err)
xcffib.ConnectionException: xcb connection errors because of socket, pipe and other stream errors.
2021-02-03 15:56:18,361 ERROR libqtile manager.py:handle_exception():L77 xcb connection errors because of socket, pipe and other stream errors.
Traceback (most recent call last):
  File "/usr/lib/python3.9/asyncio/events.py", line 80, in _run
    self._context.run(self._callback, *self._args)
  File "/usr/lib/python3.9/site-packages/libqtile/core/manager.py", line 913, in f
    func(*args)
  File "/usr/lib/python3.9/site-packages/libqtile/bar.py", line 372, in _actual_draw
    i.draw()
  File "/usr/lib/python3.9/site-packages/libqtile/widget/groupbox.py", line 373, in draw
    self.drawer.draw(offsetx=self.offset, width=self.width)
  File "/usr/lib/python3.9/site-packages/libqtile/drawer.py", line 305, in draw
    self.qtile.conn.conn.core.CopyArea(
  File "/usr/lib/python3.9/site-packages/xcffib/xproto.py", line 3035, in CopyArea
    return self.send_request(62, buf, is_checked=is_checked)
  File "/usr/lib/python3.9/site-packages/xcffib/__init__.py", line 391, in send_request
    seq = self.conn.send_request(flags, xcb_parts + 2, xcb_req)
  File "/usr/lib/python3.9/site-packages/xcffib/__init__.py", line 569, in wrapper
    self.invalid()
  File "/usr/lib/python3.9/site-packages/xcffib/__init__.py", line 559, in invalid
    raise ConnectionException(err)
xcffib.ConnectionException: xcb connection errors because of socket, pipe and other stream errors.
2021-02-03 15:56:18,363 ERROR libqtile manager.py:finalize():L320 exception during finalize
Traceback (most recent call last):
  File "/usr/lib/python3.9/site-packages/libqtile/core/manager.py", line 310, in finalize
    widget.finalize()
  File "/usr/lib/python3.9/site-packages/libqtile/widget/base.py", line 208, in finalize
    self.drawer.finalize()
  File "/usr/lib/python3.9/site-packages/libqtile/drawer.py", line 247, in finalize
    self.qtile.conn.conn.core.FreeGC(self.gc)
  File "/usr/lib/python3.9/site-packages/xcffib/xproto.py", line 3027, in FreeGC
    return self.send_request(60, buf, is_checked=is_checked)
  File "/usr/lib/python3.9/site-packages/xcffib/__init__.py", line 391, in send_request
    seq = self.conn.send_request(flags, xcb_parts + 2, xcb_req)
  File "/usr/lib/python3.9/site-packages/xcffib/__init__.py", line 569, in wrapper
    self.invalid()
  File "/usr/lib/python3.9/site-packages/xcffib/__init__.py", line 559, in invalid
    raise ConnectionException(err)
xcffib.ConnectionException: xcb connection errors because of socket, pipe and other stream errors.
2021-02-04 00:45:08,691 ERROR libqtile manager.py:handle_exception():L77 xcb connection errors because of socket, pipe and other stream errors.
Traceback (most recent call last):
  File "/usr/lib/python3.9/asyncio/events.py", line 80, in _run
    self._context.run(self._callback, *self._args)
  File "/usr/lib/python3.9/site-packages/libqtile/core/manager.py", line 914, in f
    self.conn.flush()
  File "/usr/lib/python3.9/site-packages/libqtile/backend/x11/xcbq.py", line 899, in flush
    return self.conn.flush()
  File "/usr/lib/python3.9/site-packages/xcffib/__init__.py", line 573, in wrapper
    self.invalid()
  File "/usr/lib/python3.9/site-packages/xcffib/__init__.py", line 559, in invalid
    raise ConnectionException(err)
xcffib.ConnectionException: xcb connection errors because of socket, pipe and other stream errors.
2021-02-04 00:45:08,726 ERROR libqtile manager.py:get_interesting_pid():L631 Got an exception in getting the window pid
Traceback (most recent call last):
  File "/usr/lib/python3.9/site-packages/libqtile/core/manager.py", line 629, in get_interesting_pid
    return win.window.get_net_wm_pid()
  File "/usr/lib/python3.9/site-packages/libqtile/backend/x11/xcbq.py", line 612, in get_net_wm_pid
    r = self.get_property("_NET_WM_PID", unpack=int)
  File "/usr/lib/python3.9/site-packages/libqtile/backend/x11/xcbq.py", line 705, in get_property
    r = self.conn.conn.core.GetProperty(
  File "/usr/lib/python3.9/site-packages/xcffib/xproto.py", line 2720, in GetProperty
    return self.send_request(20, buf, GetPropertyCookie, is_checked=is_checked)
  File "/usr/lib/python3.9/site-packages/xcffib/__init__.py", line 391, in send_request
    seq = self.conn.send_request(flags, xcb_parts + 2, xcb_req)
  File "/usr/lib/python3.9/site-packages/xcffib/__init__.py", line 569, in wrapper
    self.invalid()
  File "/usr/lib/python3.9/site-packages/xcffib/__init__.py", line 559, in invalid
    raise ConnectionException(err)
xcffib.ConnectionException: xcb connection errors because of socket, pipe and other stream errors.
2021-02-04 00:45:08,727 ERROR libqtile manager.py:get_interesting_pid():L631 Got an exception in getting the window pid
Traceback (most recent call last):
  File "/usr/lib/python3.9/site-packages/libqtile/core/manager.py", line 629, in get_interesting_pid
    return win.window.get_net_wm_pid()
  File "/usr/lib/python3.9/site-packages/libqtile/backend/x11/xcbq.py", line 612, in get_net_wm_pid
    r = self.get_property("_NET_WM_PID", unpack=int)
  File "/usr/lib/python3.9/site-packages/libqtile/backend/x11/xcbq.py", line 705, in get_property
    r = self.conn.conn.core.GetProperty(
  File "/usr/lib/python3.9/site-packages/xcffib/xproto.py", line 2720, in GetProperty
    return self.send_request(20, buf, GetPropertyCookie, is_checked=is_checked)
  File "/usr/lib/python3.9/site-packages/xcffib/__init__.py", line 391, in send_request
    seq = self.conn.send_request(flags, xcb_parts + 2, xcb_req)
  File "/usr/lib/python3.9/site-packages/xcffib/__init__.py", line 569, in wrapper
    self.invalid()
  File "/usr/lib/python3.9/site-packages/xcffib/__init__.py", line 559, in invalid
    raise ConnectionException(err)
xcffib.ConnectionException: xcb connection errors because of socket, pipe and other stream errors.
2021-02-04 00:45:08,728 ERROR libqtile manager.py:get_interesting_pid():L631 Got an exception in getting the window pid
Traceback (most recent call last):
  File "/usr/lib/python3.9/site-packages/libqtile/core/manager.py", line 629, in get_interesting_pid
    return win.window.get_net_wm_pid()
  File "/usr/lib/python3.9/site-packages/libqtile/backend/x11/xcbq.py", line 612, in get_net_wm_pid
    r = self.get_property("_NET_WM_PID", unpack=int)
  File "/usr/lib/python3.9/site-packages/libqtile/backend/x11/xcbq.py", line 705, in get_property
    r = self.conn.conn.core.GetProperty(
  File "/usr/lib/python3.9/site-packages/xcffib/xproto.py", line 2720, in GetProperty
    return self.send_request(20, buf, GetPropertyCookie, is_checked=is_checked)
  File "/usr/lib/python3.9/site-packages/xcffib/__init__.py", line 391, in send_request
    seq = self.conn.send_request(flags, xcb_parts + 2, xcb_req)
  File "/usr/lib/python3.9/site-packages/xcffib/__init__.py", line 569, in wrapper
    self.invalid()
  File "/usr/lib/python3.9/site-packages/xcffib/__init__.py", line 559, in invalid
    raise ConnectionException(err)
xcffib.ConnectionException: xcb connection errors because of socket, pipe and other stream errors.
2021-02-04 00:45:08,728 ERROR libqtile manager.py:get_interesting_pid():L631 Got an exception in getting the window pid
Traceback (most recent call last):
  File "/usr/lib/python3.9/site-packages/libqtile/core/manager.py", line 629, in get_interesting_pid
    return win.window.get_net_wm_pid()
  File "/usr/lib/python3.9/site-packages/libqtile/backend/x11/xcbq.py", line 612, in get_net_wm_pid
    r = self.get_property("_NET_WM_PID", unpack=int)
  File "/usr/lib/python3.9/site-packages/libqtile/backend/x11/xcbq.py", line 705, in get_property
    r = self.conn.conn.core.GetProperty(
  File "/usr/lib/python3.9/site-packages/xcffib/xproto.py", line 2720, in GetProperty
    return self.send_request(20, buf, GetPropertyCookie, is_checked=is_checked)
  File "/usr/lib/python3.9/site-packages/xcffib/__init__.py", line 391, in send_request
    seq = self.conn.send_request(flags, xcb_parts + 2, xcb_req)
  File "/usr/lib/python3.9/site-packages/xcffib/__init__.py", line 569, in wrapper
    self.invalid()
  File "/usr/lib/python3.9/site-packages/xcffib/__init__.py", line 559, in invalid
    raise ConnectionException(err)
xcffib.ConnectionException: xcb connection errors because of socket, pipe and other stream errors.
2021-02-04 00:45:08,728 ERROR libqtile xcore.py:_xpoll():L269 Shutting down due to X connection error XCB_CONN_ERROR (1)
Traceback (most recent call last):
  File "/usr/lib/python3.9/site-packages/libqtile/backend/x11/xcore.py", line 230, in _xpoll
    event = self.conn.conn.poll_for_event()
  File "/usr/lib/python3.9/site-packages/xcffib/__init__.py", line 569, in wrapper
    self.invalid()
  File "/usr/lib/python3.9/site-packages/xcffib/__init__.py", line 559, in invalid
    raise ConnectionException(err)
xcffib.ConnectionException: xcb connection errors because of socket, pipe and other stream errors.
2021-02-04 00:45:08,729 ERROR libqtile manager.py:get_interesting_pid():L631 Got an exception in getting the window pid
Traceback (most recent call last):
  File "/usr/lib/python3.9/site-packages/libqtile/backend/x11/xcore.py", line 230, in _xpoll
    event = self.conn.conn.poll_for_event()
  File "/usr/lib/python3.9/site-packages/xcffib/__init__.py", line 569, in wrapper
    self.invalid()
  File "/usr/lib/python3.9/site-packages/xcffib/__init__.py", line 559, in invalid
    raise ConnectionException(err)
xcffib.ConnectionException: xcb connection errors because of socket, pipe and other stream errors.

During handling of the above exception, another exception occurred:

Traceback (most recent call last):
  File "/usr/lib/python3.9/site-packages/libqtile/core/manager.py", line 629, in get_interesting_pid
    return win.window.get_net_wm_pid()
  File "/usr/lib/python3.9/site-packages/libqtile/backend/x11/xcbq.py", line 612, in get_net_wm_pid
    r = self.get_property("_NET_WM_PID", unpack=int)
  File "/usr/lib/python3.9/site-packages/libqtile/backend/x11/xcbq.py", line 705, in get_property
    r = self.conn.conn.core.GetProperty(
  File "/usr/lib/python3.9/site-packages/xcffib/xproto.py", line 2720, in GetProperty
    return self.send_request(20, buf, GetPropertyCookie, is_checked=is_checked)
  File "/usr/lib/python3.9/site-packages/xcffib/__init__.py", line 391, in send_request
    seq = self.conn.send_request(flags, xcb_parts + 2, xcb_req)
  File "/usr/lib/python3.9/site-packages/xcffib/__init__.py", line 569, in wrapper
    self.invalid()
  File "/usr/lib/python3.9/site-packages/xcffib/__init__.py", line 559, in invalid
    raise ConnectionException(err)
xcffib.ConnectionException: xcb connection errors because of socket, pipe and other stream errors.
2021-02-04 00:45:08,729 ERROR libqtile manager.py:get_interesting_pid():L631 Got an exception in getting the window pid
Traceback (most recent call last):
  File "/usr/lib/python3.9/site-packages/libqtile/backend/x11/xcore.py", line 230, in _xpoll
    event = self.conn.conn.poll_for_event()
  File "/usr/lib/python3.9/site-packages/xcffib/__init__.py", line 569, in wrapper
    self.invalid()
  File "/usr/lib/python3.9/site-packages/xcffib/__init__.py", line 559, in invalid
    raise ConnectionException(err)
xcffib.ConnectionException: xcb connection errors because of socket, pipe and other stream errors.

During handling of the above exception, another exception occurred:

Traceback (most recent call last):
  File "/usr/lib/python3.9/site-packages/libqtile/core/manager.py", line 629, in get_interesting_pid
    return win.window.get_net_wm_pid()
  File "/usr/lib/python3.9/site-packages/libqtile/backend/x11/xcbq.py", line 612, in get_net_wm_pid
    r = self.get_property("_NET_WM_PID", unpack=int)
  File "/usr/lib/python3.9/site-packages/libqtile/backend/x11/xcbq.py", line 705, in get_property
    r = self.conn.conn.core.GetProperty(
  File "/usr/lib/python3.9/site-packages/xcffib/xproto.py", line 2720, in GetProperty
    return self.send_request(20, buf, GetPropertyCookie, is_checked=is_checked)
  File "/usr/lib/python3.9/site-packages/xcffib/__init__.py", line 391, in send_request
    seq = self.conn.send_request(flags, xcb_parts + 2, xcb_req)
  File "/usr/lib/python3.9/site-packages/xcffib/__init__.py", line 569, in wrapper
    self.invalid()
  File "/usr/lib/python3.9/site-packages/xcffib/__init__.py", line 559, in invalid
    raise ConnectionException(err)
xcffib.ConnectionException: xcb connection errors because of socket, pipe and other stream errors.
2021-02-04 00:45:08,731 ERROR libqtile base.py:_wrapper():L294 got exception from widget timer
Traceback (most recent call last):
  File "/usr/lib/python3.9/site-packages/libqtile/widget/base.py", line 292, in _wrapper
    method(*method_args)
  File "/usr/lib/python3.9/site-packages/libqtile/widget/graph.py", line 182, in update
    self.update_graph()
  File "/usr/lib/python3.9/site-packages/libqtile/widget/graph.py", line 231, in update_graph
    self.push(push_value)
  File "/usr/lib/python3.9/site-packages/libqtile/widget/graph.py", line 174, in push
    self.draw()
  File "/usr/lib/python3.9/site-packages/libqtile/widget/graph.py", line 161, in draw
    self.drawer.draw(offsetx=self.offset, width=self.width)
  File "/usr/lib/python3.9/site-packages/libqtile/drawer.py", line 305, in draw
    self.qtile.conn.conn.core.CopyArea(
  File "/usr/lib/python3.9/site-packages/xcffib/xproto.py", line 3035, in CopyArea
    return self.send_request(62, buf, is_checked=is_checked)
  File "/usr/lib/python3.9/site-packages/xcffib/__init__.py", line 391, in send_request
    seq = self.conn.send_request(flags, xcb_parts + 2, xcb_req)
  File "/usr/lib/python3.9/site-packages/xcffib/__init__.py", line 569, in wrapper
    self.invalid()
  File "/usr/lib/python3.9/site-packages/xcffib/__init__.py", line 559, in invalid
    raise ConnectionException(err)
xcffib.ConnectionException: xcb connection errors because of socket, pipe and other stream errors.
2021-02-04 00:45:08,732 ERROR libqtile manager.py:handle_exception():L77 xcb connection errors because of socket, pipe and other stream errors.
Traceback (most recent call last):
  File "/usr/lib/python3.9/asyncio/events.py", line 80, in _run
    self._context.run(self._callback, *self._args)
  File "/usr/lib/python3.9/site-packages/libqtile/core/manager.py", line 928, in f
    self.conn.flush()
  File "/usr/lib/python3.9/site-packages/libqtile/backend/x11/xcbq.py", line 899, in flush
    return self.conn.flush()
  File "/usr/lib/python3.9/site-packages/xcffib/__init__.py", line 569, in wrapper
    self.invalid()
  File "/usr/lib/python3.9/site-packages/xcffib/__init__.py", line 559, in invalid
    raise ConnectionException(err)
xcffib.ConnectionException: xcb connection errors because of socket, pipe and other stream errors.
2021-02-04 00:45:08,733 ERROR libqtile base.py:_wrapper():L294 got exception from widget timer
Traceback (most recent call last):
  File "/usr/lib/python3.9/site-packages/libqtile/widget/base.py", line 292, in _wrapper
    method(*method_args)
  File "/usr/lib/python3.9/site-packages/libqtile/widget/base.py", line 457, in timer_setup
    update_interval = self.tick()
  File "/usr/lib/python3.9/site-packages/libqtile/widget/memory.py", line 59, in tick
    self.update(self.poll())
  File "/usr/lib/python3.9/site-packages/libqtile/widget/base.py", line 493, in update
    self.draw()
  File "/usr/lib/python3.9/site-packages/libqtile/widget/base.py", line 416, in draw
    self.drawer.draw(offsetx=self.offsetx, width=self.width)
  File "/usr/lib/python3.9/site-packages/libqtile/drawer.py", line 305, in draw
    self.qtile.conn.conn.core.CopyArea(
  File "/usr/lib/python3.9/site-packages/xcffib/xproto.py", line 3035, in CopyArea
    return self.send_request(62, buf, is_checked=is_checked)
  File "/usr/lib/python3.9/site-packages/xcffib/__init__.py", line 391, in send_request
    seq = self.conn.send_request(flags, xcb_parts + 2, xcb_req)
  File "/usr/lib/python3.9/site-packages/xcffib/__init__.py", line 569, in wrapper
    self.invalid()
  File "/usr/lib/python3.9/site-packages/xcffib/__init__.py", line 559, in invalid
    raise ConnectionException(err)
xcffib.ConnectionException: xcb connection errors because of socket, pipe and other stream errors.
2021-02-04 00:45:08,733 ERROR libqtile manager.py:handle_exception():L77 xcb connection errors because of socket, pipe and other stream errors.
Traceback (most recent call last):
  File "/usr/lib/python3.9/asyncio/events.py", line 80, in _run
    self._context.run(self._callback, *self._args)
  File "/usr/lib/python3.9/site-packages/libqtile/core/manager.py", line 928, in f
    self.conn.flush()
  File "/usr/lib/python3.9/site-packages/libqtile/backend/x11/xcbq.py", line 899, in flush
    return self.conn.flush()
  File "/usr/lib/python3.9/site-packages/xcffib/__init__.py", line 569, in wrapper
    self.invalid()
  File "/usr/lib/python3.9/site-packages/xcffib/__init__.py", line 559, in invalid
    raise ConnectionException(err)
xcffib.ConnectionException: xcb connection errors because of socket, pipe and other stream errors.
2021-02-04 00:45:08,736 ERROR libqtile manager.py:finalize():L320 exception during finalize
Traceback (most recent call last):
  File "/usr/lib/python3.9/site-packages/libqtile/core/manager.py", line 310, in finalize
    widget.finalize()
  File "/usr/lib/python3.9/site-packages/libqtile/widget/base.py", line 208, in finalize
    self.drawer.finalize()
  File "/usr/lib/python3.9/site-packages/libqtile/drawer.py", line 247, in finalize
    self.qtile.conn.conn.core.FreeGC(self.gc)
  File "/usr/lib/python3.9/site-packages/xcffib/xproto.py", line 3027, in FreeGC
    return self.send_request(60, buf, is_checked=is_checked)
  File "/usr/lib/python3.9/site-packages/xcffib/__init__.py", line 391, in send_request
    seq = self.conn.send_request(flags, xcb_parts + 2, xcb_req)
  File "/usr/lib/python3.9/site-packages/xcffib/__init__.py", line 569, in wrapper
    self.invalid()
  File "/usr/lib/python3.9/site-packages/xcffib/__init__.py", line 559, in invalid
    raise ConnectionException(err)
xcffib.ConnectionException: xcb connection errors because of socket, pipe and other stream errors.
2021-02-09 00:09:22,125 WARNING libqtile manager.py:maybe_restart():L269 Restarting Qtile with os.execv(...)
2021-02-09 00:17:53,080 ERROR libqtile xcore.py:_xpoll():L269 Shutting down due to X connection error XCB_CONN_ERROR (1)
Traceback (most recent call last):
  File "/usr/lib/python3.9/site-packages/xcffib/__init__.py", line 571, in wrapper
    return f(*args)
  File "/usr/lib/python3.9/site-packages/xcffib/__init__.py", line 681, in request_check
    self._process_error(err)
  File "/usr/lib/python3.9/site-packages/xcffib/__init__.py", line 645, in _process_error
    self.invalid()
  File "/usr/lib/python3.9/site-packages/xcffib/__init__.py", line 559, in invalid
    raise ConnectionException(err)
xcffib.ConnectionException: xcb connection errors because of socket, pipe and other stream errors.

During handling of the above exception, another exception occurred:

Traceback (most recent call last):
  File "/usr/lib/python3.9/site-packages/libqtile/backend/x11/xcore.py", line 245, in _xpoll
    ret = target(event)
  File "/usr/lib/python3.9/site-packages/libqtile/backend/x11/xcore.py", line 600, in handle_UnmapNotify
    self.qtile.unmap_window(event.window)
  File "/usr/lib/python3.9/site-packages/libqtile/core/manager.py", line 553, in unmap_window
    c.state = window.WithdrawnState
  File "/usr/lib/python3.9/site-packages/libqtile/window.py", line 370, in state
    self.window.set_property('WM_STATE', [val, 0])
  File "/usr/lib/python3.9/site-packages/libqtile/backend/x11/xcbq.py", line 676, in set_property
    self.conn.conn.core.ChangePropertyChecked(
  File "/usr/lib/python3.9/site-packages/xcffib/__init__.py", line 339, in check
    self.conn.request_check(self.sequence)
  File "/usr/lib/python3.9/site-packages/xcffib/__init__.py", line 573, in wrapper
    self.invalid()
  File "/usr/lib/python3.9/site-packages/xcffib/__init__.py", line 559, in invalid
    raise ConnectionException(err)
xcffib.ConnectionException: xcb connection errors because of socket, pipe and other stream errors.
2021-02-09 00:19:44,009 ERROR libqtile xcore.py:_xpoll():L269 Shutting down due to X connection error XCB_CONN_ERROR (1)
Traceback (most recent call last):
  File "/usr/lib/python3.9/site-packages/xcffib/__init__.py", line 571, in wrapper
    return f(*args)
  File "/usr/lib/python3.9/site-packages/xcffib/__init__.py", line 681, in request_check
    self._process_error(err)
  File "/usr/lib/python3.9/site-packages/xcffib/__init__.py", line 645, in _process_error
    self.invalid()
  File "/usr/lib/python3.9/site-packages/xcffib/__init__.py", line 559, in invalid
    raise ConnectionException(err)
xcffib.ConnectionException: xcb connection errors because of socket, pipe and other stream errors.

During handling of the above exception, another exception occurred:

Traceback (most recent call last):
  File "/usr/lib/python3.9/site-packages/libqtile/backend/x11/xcore.py", line 245, in _xpoll
    ret = target(event)
  File "/usr/lib/python3.9/site-packages/libqtile/backend/x11/xcore.py", line 600, in handle_UnmapNotify
    self.qtile.unmap_window(event.window)
  File "/usr/lib/python3.9/site-packages/libqtile/core/manager.py", line 553, in unmap_window
    c.state = window.WithdrawnState
  File "/usr/lib/python3.9/site-packages/libqtile/window.py", line 370, in state
    self.window.set_property('WM_STATE', [val, 0])
  File "/usr/lib/python3.9/site-packages/libqtile/backend/x11/xcbq.py", line 676, in set_property
    self.conn.conn.core.ChangePropertyChecked(
  File "/usr/lib/python3.9/site-packages/xcffib/__init__.py", line 339, in check
    self.conn.request_check(self.sequence)
  File "/usr/lib/python3.9/site-packages/xcffib/__init__.py", line 573, in wrapper
    self.invalid()
  File "/usr/lib/python3.9/site-packages/xcffib/__init__.py", line 559, in invalid
    raise ConnectionException(err)
xcffib.ConnectionException: xcb connection errors because of socket, pipe and other stream errors.
2021-02-09 00:19:44,030 ERROR libqtile manager.py:get_interesting_pid():L631 Got an exception in getting the window pid
Traceback (most recent call last):
  File "/usr/lib/python3.9/site-packages/xcffib/__init__.py", line 571, in wrapper
    return f(*args)
  File "/usr/lib/python3.9/site-packages/xcffib/__init__.py", line 681, in request_check
    self._process_error(err)
  File "/usr/lib/python3.9/site-packages/xcffib/__init__.py", line 645, in _process_error
    self.invalid()
  File "/usr/lib/python3.9/site-packages/xcffib/__init__.py", line 559, in invalid
    raise ConnectionException(err)
xcffib.ConnectionException: xcb connection errors because of socket, pipe and other stream errors.

During handling of the above exception, another exception occurred:

Traceback (most recent call last):
  File "/usr/lib/python3.9/site-packages/libqtile/backend/x11/xcore.py", line 245, in _xpoll
    ret = target(event)
  File "/usr/lib/python3.9/site-packages/libqtile/backend/x11/xcore.py", line 600, in handle_UnmapNotify
    self.qtile.unmap_window(event.window)
  File "/usr/lib/python3.9/site-packages/libqtile/core/manager.py", line 553, in unmap_window
    c.state = window.WithdrawnState
  File "/usr/lib/python3.9/site-packages/libqtile/window.py", line 370, in state
    self.window.set_property('WM_STATE', [val, 0])
  File "/usr/lib/python3.9/site-packages/libqtile/backend/x11/xcbq.py", line 676, in set_property
    self.conn.conn.core.ChangePropertyChecked(
  File "/usr/lib/python3.9/site-packages/xcffib/__init__.py", line 339, in check
    self.conn.request_check(self.sequence)
  File "/usr/lib/python3.9/site-packages/xcffib/__init__.py", line 573, in wrapper
    self.invalid()
  File "/usr/lib/python3.9/site-packages/xcffib/__init__.py", line 559, in invalid
    raise ConnectionException(err)
xcffib.ConnectionException: xcb connection errors because of socket, pipe and other stream errors.

During handling of the above exception, another exception occurred:

Traceback (most recent call last):
  File "/usr/lib/python3.9/site-packages/libqtile/core/manager.py", line 629, in get_interesting_pid
    return win.window.get_net_wm_pid()
  File "/usr/lib/python3.9/site-packages/libqtile/backend/x11/xcbq.py", line 612, in get_net_wm_pid
    r = self.get_property("_NET_WM_PID", unpack=int)
  File "/usr/lib/python3.9/site-packages/libqtile/backend/x11/xcbq.py", line 705, in get_property
    r = self.conn.conn.core.GetProperty(
  File "/usr/lib/python3.9/site-packages/xcffib/xproto.py", line 2720, in GetProperty
    return self.send_request(20, buf, GetPropertyCookie, is_checked=is_checked)
  File "/usr/lib/python3.9/site-packages/xcffib/__init__.py", line 391, in send_request
    seq = self.conn.send_request(flags, xcb_parts + 2, xcb_req)
  File "/usr/lib/python3.9/site-packages/xcffib/__init__.py", line 569, in wrapper
    self.invalid()
  File "/usr/lib/python3.9/site-packages/xcffib/__init__.py", line 559, in invalid
    raise ConnectionException(err)
xcffib.ConnectionException: xcb connection errors because of socket, pipe and other stream errors.
2021-02-15 18:11:45,026 ERROR libqtile xcore.py:_xpoll():L269 Shutting down due to X connection error XCB_CONN_ERROR (1)
Traceback (most recent call last):
  File "/usr/lib/python3.9/site-packages/xcffib/__init__.py", line 571, in wrapper
    return f(*args)
  File "/usr/lib/python3.9/site-packages/xcffib/__init__.py", line 610, in poll_for_event
    self.invalid()
  File "/usr/lib/python3.9/site-packages/xcffib/__init__.py", line 559, in invalid
    raise ConnectionException(err)
xcffib.ConnectionException: xcb connection errors because of socket, pipe and other stream errors.

During handling of the above exception, another exception occurred:

Traceback (most recent call last):
  File "/usr/lib/python3.9/site-packages/libqtile/backend/x11/xcore.py", line 230, in _xpoll
    event = self.conn.conn.poll_for_event()
  File "/usr/lib/python3.9/site-packages/xcffib/__init__.py", line 573, in wrapper
    self.invalid()
  File "/usr/lib/python3.9/site-packages/xcffib/__init__.py", line 559, in invalid
    raise ConnectionException(err)
xcffib.ConnectionException: xcb connection errors because of socket, pipe and other stream errors.
2021-02-15 18:11:45,572 ERROR libqtile manager.py:get_interesting_pid():L631 Got an exception in getting the window pid
Traceback (most recent call last):
  File "/usr/lib/python3.9/site-packages/xcffib/__init__.py", line 571, in wrapper
    return f(*args)
  File "/usr/lib/python3.9/site-packages/xcffib/__init__.py", line 610, in poll_for_event
    self.invalid()
  File "/usr/lib/python3.9/site-packages/xcffib/__init__.py", line 559, in invalid
    raise ConnectionException(err)
xcffib.ConnectionException: xcb connection errors because of socket, pipe and other stream errors.

During handling of the above exception, another exception occurred:

Traceback (most recent call last):
  File "/usr/lib/python3.9/site-packages/libqtile/backend/x11/xcore.py", line 230, in _xpoll
    event = self.conn.conn.poll_for_event()
  File "/usr/lib/python3.9/site-packages/xcffib/__init__.py", line 573, in wrapper
    self.invalid()
  File "/usr/lib/python3.9/site-packages/xcffib/__init__.py", line 559, in invalid
    raise ConnectionException(err)
xcffib.ConnectionException: xcb connection errors because of socket, pipe and other stream errors.

During handling of the above exception, another exception occurred:

Traceback (most recent call last):
  File "/usr/lib/python3.9/site-packages/libqtile/core/manager.py", line 629, in get_interesting_pid
    return win.window.get_net_wm_pid()
  File "/usr/lib/python3.9/site-packages/libqtile/backend/x11/xcbq.py", line 612, in get_net_wm_pid
    r = self.get_property("_NET_WM_PID", unpack=int)
  File "/usr/lib/python3.9/site-packages/libqtile/backend/x11/xcbq.py", line 705, in get_property
    r = self.conn.conn.core.GetProperty(
  File "/usr/lib/python3.9/site-packages/xcffib/xproto.py", line 2720, in GetProperty
    return self.send_request(20, buf, GetPropertyCookie, is_checked=is_checked)
  File "/usr/lib/python3.9/site-packages/xcffib/__init__.py", line 391, in send_request
    seq = self.conn.send_request(flags, xcb_parts + 2, xcb_req)
  File "/usr/lib/python3.9/site-packages/xcffib/__init__.py", line 569, in wrapper
    self.invalid()
  File "/usr/lib/python3.9/site-packages/xcffib/__init__.py", line 559, in invalid
    raise ConnectionException(err)
xcffib.ConnectionException: xcb connection errors because of socket, pipe and other stream errors.
2021-02-15 18:11:45,683 ERROR libqtile manager.py:get_interesting_pid():L631 Got an exception in getting the window pid
Traceback (most recent call last):
  File "/usr/lib/python3.9/site-packages/libqtile/core/manager.py", line 629, in get_interesting_pid
    return win.window.get_net_wm_pid()
  File "/usr/lib/python3.9/site-packages/libqtile/backend/x11/xcbq.py", line 612, in get_net_wm_pid
    r = self.get_property("_NET_WM_PID", unpack=int)
  File "/usr/lib/python3.9/site-packages/libqtile/backend/x11/xcbq.py", line 705, in get_property
    r = self.conn.conn.core.GetProperty(
  File "/usr/lib/python3.9/site-packages/xcffib/xproto.py", line 2720, in GetProperty
    return self.send_request(20, buf, GetPropertyCookie, is_checked=is_checked)
  File "/usr/lib/python3.9/site-packages/xcffib/__init__.py", line 391, in send_request
    seq = self.conn.send_request(flags, xcb_parts + 2, xcb_req)
  File "/usr/lib/python3.9/site-packages/xcffib/__init__.py", line 569, in wrapper
    self.invalid()
  File "/usr/lib/python3.9/site-packages/xcffib/__init__.py", line 559, in invalid
    raise ConnectionException(err)
xcffib.ConnectionException: xcb connection errors because of socket, pipe and other stream errors.
2021-02-15 18:11:45,683 ERROR libqtile manager.py:get_interesting_pid():L631 Got an exception in getting the window pid
Traceback (most recent call last):
  File "/usr/lib/python3.9/site-packages/libqtile/core/manager.py", line 629, in get_interesting_pid
    return win.window.get_net_wm_pid()
  File "/usr/lib/python3.9/site-packages/libqtile/backend/x11/xcbq.py", line 612, in get_net_wm_pid
    r = self.get_property("_NET_WM_PID", unpack=int)
  File "/usr/lib/python3.9/site-packages/libqtile/backend/x11/xcbq.py", line 705, in get_property
    r = self.conn.conn.core.GetProperty(
  File "/usr/lib/python3.9/site-packages/xcffib/xproto.py", line 2720, in GetProperty
    return self.send_request(20, buf, GetPropertyCookie, is_checked=is_checked)
  File "/usr/lib/python3.9/site-packages/xcffib/__init__.py", line 391, in send_request
    seq = self.conn.send_request(flags, xcb_parts + 2, xcb_req)
  File "/usr/lib/python3.9/site-packages/xcffib/__init__.py", line 569, in wrapper
    self.invalid()
  File "/usr/lib/python3.9/site-packages/xcffib/__init__.py", line 559, in invalid
    raise ConnectionException(err)
xcffib.ConnectionException: xcb connection errors because of socket, pipe and other stream errors.
2021-02-15 18:11:45,688 ERROR libqtile manager.py:handle_exception():L77 xcb connection errors because of socket, pipe and other stream errors.
Traceback (most recent call last):
  File "/usr/lib/python3.9/asyncio/events.py", line 80, in _run
    self._context.run(self._callback, *self._args)
  File "/usr/lib/python3.9/site-packages/libqtile/core/manager.py", line 913, in f
    func(*args)
  File "/usr/lib/python3.9/site-packages/libqtile/bar.py", line 372, in _actual_draw
    i.draw()
  File "/usr/lib/python3.9/site-packages/libqtile/widget/groupbox.py", line 373, in draw
    self.drawer.draw(offsetx=self.offset, width=self.width)
  File "/usr/lib/python3.9/site-packages/libqtile/drawer.py", line 305, in draw
    self.qtile.conn.conn.core.CopyArea(
  File "/usr/lib/python3.9/site-packages/xcffib/xproto.py", line 3035, in CopyArea
    return self.send_request(62, buf, is_checked=is_checked)
  File "/usr/lib/python3.9/site-packages/xcffib/__init__.py", line 391, in send_request
    seq = self.conn.send_request(flags, xcb_parts + 2, xcb_req)
  File "/usr/lib/python3.9/site-packages/xcffib/__init__.py", line 569, in wrapper
    self.invalid()
  File "/usr/lib/python3.9/site-packages/xcffib/__init__.py", line 559, in invalid
    raise ConnectionException(err)
xcffib.ConnectionException: xcb connection errors because of socket, pipe and other stream errors.
2021-02-15 18:11:45,845 ERROR libqtile base.py:_wrapper():L294 got exception from widget timer
Traceback (most recent call last):
  File "/usr/lib/python3.9/site-packages/libqtile/widget/base.py", line 292, in _wrapper
    method(*method_args)
  File "/usr/lib/python3.9/site-packages/libqtile/widget/graph.py", line 182, in update
    self.update_graph()
  File "/usr/lib/python3.9/site-packages/libqtile/widget/graph.py", line 231, in update_graph
    self.push(push_value)
  File "/usr/lib/python3.9/site-packages/libqtile/widget/graph.py", line 174, in push
    self.draw()
  File "/usr/lib/python3.9/site-packages/libqtile/widget/graph.py", line 161, in draw
    self.drawer.draw(offsetx=self.offset, width=self.width)
  File "/usr/lib/python3.9/site-packages/libqtile/drawer.py", line 305, in draw
    self.qtile.conn.conn.core.CopyArea(
  File "/usr/lib/python3.9/site-packages/xcffib/xproto.py", line 3035, in CopyArea
    return self.send_request(62, buf, is_checked=is_checked)
  File "/usr/lib/python3.9/site-packages/xcffib/__init__.py", line 391, in send_request
    seq = self.conn.send_request(flags, xcb_parts + 2, xcb_req)
  File "/usr/lib/python3.9/site-packages/xcffib/__init__.py", line 569, in wrapper
    self.invalid()
  File "/usr/lib/python3.9/site-packages/xcffib/__init__.py", line 559, in invalid
    raise ConnectionException(err)
xcffib.ConnectionException: xcb connection errors because of socket, pipe and other stream errors.
2021-02-15 18:11:45,859 ERROR libqtile base.py:_wrapper():L294 got exception from widget timer
Traceback (most recent call last):
  File "/usr/lib/python3.9/site-packages/libqtile/widget/base.py", line 292, in _wrapper
    method(*method_args)
  File "/usr/lib/python3.9/site-packages/libqtile/widget/base.py", line 457, in timer_setup
    update_interval = self.tick()
  File "/usr/lib/python3.9/site-packages/libqtile/widget/memory.py", line 59, in tick
    self.update(self.poll())
  File "/usr/lib/python3.9/site-packages/libqtile/widget/base.py", line 493, in update
    self.draw()
  File "/usr/lib/python3.9/site-packages/libqtile/widget/base.py", line 416, in draw
    self.drawer.draw(offsetx=self.offsetx, width=self.width)
  File "/usr/lib/python3.9/site-packages/libqtile/drawer.py", line 305, in draw
    self.qtile.conn.conn.core.CopyArea(
  File "/usr/lib/python3.9/site-packages/xcffib/xproto.py", line 3035, in CopyArea
    return self.send_request(62, buf, is_checked=is_checked)
  File "/usr/lib/python3.9/site-packages/xcffib/__init__.py", line 391, in send_request
    seq = self.conn.send_request(flags, xcb_parts + 2, xcb_req)
  File "/usr/lib/python3.9/site-packages/xcffib/__init__.py", line 569, in wrapper
    self.invalid()
  File "/usr/lib/python3.9/site-packages/xcffib/__init__.py", line 559, in invalid
    raise ConnectionException(err)
xcffib.ConnectionException: xcb connection errors because of socket, pipe and other stream errors.
2021-02-15 18:11:45,862 ERROR libqtile manager.py:finalize():L320 exception during finalize
Traceback (most recent call last):
  File "/usr/lib/python3.9/site-packages/libqtile/core/manager.py", line 310, in finalize
    widget.finalize()
  File "/usr/lib/python3.9/site-packages/libqtile/widget/base.py", line 208, in finalize
    self.drawer.finalize()
  File "/usr/lib/python3.9/site-packages/libqtile/drawer.py", line 247, in finalize
    self.qtile.conn.conn.core.FreeGC(self.gc)
  File "/usr/lib/python3.9/site-packages/xcffib/xproto.py", line 3027, in FreeGC
    return self.send_request(60, buf, is_checked=is_checked)
  File "/usr/lib/python3.9/site-packages/xcffib/__init__.py", line 391, in send_request
    seq = self.conn.send_request(flags, xcb_parts + 2, xcb_req)
  File "/usr/lib/python3.9/site-packages/xcffib/__init__.py", line 569, in wrapper
    self.invalid()
  File "/usr/lib/python3.9/site-packages/xcffib/__init__.py", line 559, in invalid
    raise ConnectionException(err)
xcffib.ConnectionException: xcb connection errors because of socket, pipe and other stream errors.
2021-02-15 18:21:33,685 ERROR libqtile manager.py:process_key_event():L375 KB command error kill: No object window in path 'window'
2021-02-15 18:21:44,641 ERROR libqtile manager.py:get_interesting_pid():L631 Got an exception in getting the window pid
Traceback (most recent call last):
  File "/usr/lib/python3.9/site-packages/xcffib/__init__.py", line 571, in wrapper
    return f(*args)
  File "/usr/lib/python3.9/site-packages/xcffib/__init__.py", line 658, in wait_for_reply
    self._process_error(error_p[0])
  File "/usr/lib/python3.9/site-packages/xcffib/__init__.py", line 645, in _process_error
    self.invalid()
  File "/usr/lib/python3.9/site-packages/xcffib/__init__.py", line 559, in invalid
    raise ConnectionException(err)
xcffib.ConnectionException: xcb connection errors because of socket, pipe and other stream errors.

During handling of the above exception, another exception occurred:

Traceback (most recent call last):
  File "/usr/lib/python3.9/site-packages/libqtile/core/manager.py", line 629, in get_interesting_pid
    return win.window.get_net_wm_pid()
  File "/usr/lib/python3.9/site-packages/libqtile/backend/x11/xcbq.py", line 612, in get_net_wm_pid
    r = self.get_property("_NET_WM_PID", unpack=int)
  File "/usr/lib/python3.9/site-packages/libqtile/backend/x11/xcbq.py", line 705, in get_property
    r = self.conn.conn.core.GetProperty(
  File "/usr/lib/python3.9/site-packages/xcffib/__init__.py", line 332, in reply
    data = self.conn.wait_for_reply(self.sequence)
  File "/usr/lib/python3.9/site-packages/xcffib/__init__.py", line 573, in wrapper
    self.invalid()
  File "/usr/lib/python3.9/site-packages/xcffib/__init__.py", line 559, in invalid
    raise ConnectionException(err)
xcffib.ConnectionException: xcb connection errors because of socket, pipe and other stream errors.
2021-02-15 18:21:44,644 ERROR libqtile xcore.py:_xpoll():L269 Shutting down due to X connection error XCB_CONN_ERROR (1)
Traceback (most recent call last):
  File "/usr/lib/python3.9/site-packages/libqtile/backend/x11/xcore.py", line 230, in _xpoll
    event = self.conn.conn.poll_for_event()
  File "/usr/lib/python3.9/site-packages/xcffib/__init__.py", line 569, in wrapper
    self.invalid()
  File "/usr/lib/python3.9/site-packages/xcffib/__init__.py", line 559, in invalid
    raise ConnectionException(err)
xcffib.ConnectionException: xcb connection errors because of socket, pipe and other stream errors.
2021-02-15 18:21:44,644 ERROR libqtile manager.py:get_interesting_pid():L631 Got an exception in getting the window pid
Traceback (most recent call last):
  File "/usr/lib/python3.9/site-packages/libqtile/backend/x11/xcore.py", line 230, in _xpoll
    event = self.conn.conn.poll_for_event()
  File "/usr/lib/python3.9/site-packages/xcffib/__init__.py", line 569, in wrapper
    self.invalid()
  File "/usr/lib/python3.9/site-packages/xcffib/__init__.py", line 559, in invalid
    raise ConnectionException(err)
xcffib.ConnectionException: xcb connection errors because of socket, pipe and other stream errors.

During handling of the above exception, another exception occurred:

Traceback (most recent call last):
  File "/usr/lib/python3.9/site-packages/libqtile/core/manager.py", line 629, in get_interesting_pid
    return win.window.get_net_wm_pid()
  File "/usr/lib/python3.9/site-packages/libqtile/backend/x11/xcbq.py", line 612, in get_net_wm_pid
    r = self.get_property("_NET_WM_PID", unpack=int)
  File "/usr/lib/python3.9/site-packages/libqtile/backend/x11/xcbq.py", line 705, in get_property
    r = self.conn.conn.core.GetProperty(
  File "/usr/lib/python3.9/site-packages/xcffib/xproto.py", line 2720, in GetProperty
    return self.send_request(20, buf, GetPropertyCookie, is_checked=is_checked)
  File "/usr/lib/python3.9/site-packages/xcffib/__init__.py", line 391, in send_request
    seq = self.conn.send_request(flags, xcb_parts + 2, xcb_req)
  File "/usr/lib/python3.9/site-packages/xcffib/__init__.py", line 569, in wrapper
    self.invalid()
  File "/usr/lib/python3.9/site-packages/xcffib/__init__.py", line 559, in invalid
    raise ConnectionException(err)
xcffib.ConnectionException: xcb connection errors because of socket, pipe and other stream errors.
2021-02-15 18:21:44,646 ERROR libqtile manager.py:finalize():L320 exception during finalize
Traceback (most recent call last):
  File "/usr/lib/python3.9/site-packages/libqtile/core/manager.py", line 310, in finalize
    widget.finalize()
  File "/usr/lib/python3.9/site-packages/libqtile/widget/base.py", line 208, in finalize
    self.drawer.finalize()
  File "/usr/lib/python3.9/site-packages/libqtile/drawer.py", line 247, in finalize
    self.qtile.conn.conn.core.FreeGC(self.gc)
  File "/usr/lib/python3.9/site-packages/xcffib/xproto.py", line 3027, in FreeGC
    return self.send_request(60, buf, is_checked=is_checked)
  File "/usr/lib/python3.9/site-packages/xcffib/__init__.py", line 391, in send_request
    seq = self.conn.send_request(flags, xcb_parts + 2, xcb_req)
  File "/usr/lib/python3.9/site-packages/xcffib/__init__.py", line 569, in wrapper
    self.invalid()
  File "/usr/lib/python3.9/site-packages/xcffib/__init__.py", line 559, in invalid
    raise ConnectionException(err)
xcffib.ConnectionException: xcb connection errors because of socket, pipe and other stream errors.
